Workbook

Sheet README
A1: 7th Grade Math Team - Weekly Check Tracker (DPP 2026-27)
A3: Who touches what
A4: CHECKS, SCORES, RECHECKS, HUDDLE, UNITS: Croix enters. Blue text = you type it.
A5: STUDENTS and CYCLES: formulas only. Do not type there. Screenshot CYCLES for the DPP.
A7: Rules
A8: Student codes only (S01-S25 per section). The name key lives on paper in the binder.
A9: Absent = A (text). Formulas skip text, so an absent student is excluded, not zeroed.
A10: Mastery = 4 or more out of 5 on a weekly check.
A11: A cycle = a check with Retaught = y, plus RECHECKS rows for it. The re-check has 3 items on the retaught benchmark and 2 on the Comparison check's benchmark (a benchmark taught but not retaught).
A12: Net gain = (re-check % - first-check %) on the retaught benchmark, minus the same change on the comparison items. Paired students only (both scores present).
A14: This copy holds SYNTHETIC data for six weeks so you can see the formulas work. Clear SCORES, RECHECKS, HUDDLE, UNITS and CHECKS rows 2+ before real use; keep row 1.
A15: Built for import into Google Sheets (school account). Formulas use only functions Sheets supports.

Sheet CHECKS
A1: Check ID | B1: Date | C1: Benchmark | D1: Backstop (y/n) | E1: Retaught (y/n) | F1: Comparison check ID | G1: Notes
A2: W01 | B2: 46324 | C2: MA.7.NSO.2.1 | D2: n | E2: y
A3: W02 | B3: 46331 | C3: MA.7.AR.1.1 | D3: n | E3: y | F3: W01
A4: W03 | B4: 46338 | C4: MA.7.AR.1.2 | D4: n | E4: y | F4: W02
A5: W04 | B5: 46345 | C5: MA.7.AR.2.1 | D5: n | E5: y | F5: W03
A6: W05 | B6: 46352 | C6: MA.7.AR.3.1 | D6: n | E6: y | F6: W04
A7: W06 | B7: 46359 | C7: MA.7.AR.3.2 | D7: n | E7: y | F7: W05
A8: W07 | B8: 46366 | C8: MA.7.AR.4.1 | D8: n | G8: entered, re-check not yet given
A9: W08 | B9: 46373 | C9: MA.7.AR.4.2 | D9: n | G9: entered, re-check not yet given

Sheet CYCLES
A1: Reteach cycles - the DPP exhibit
A2: One row per check marked Retaught = y. Paired students only. Net gain = gain on the retaught benchmark minus the change on comparison items from a benchmark that was not retaught.
A4: Check ID | B4: Benchmark | C4: n paired | D4: First check % (retaught bm) | E4: Re-check % (3 items) | F4: Gain (pts) | G4: Comparison check | H4: n comp. paired | I4: Comparison first % | J4: Comparison re-check % (2 items) | K4: Comparison change (pts) | L4: Net gain (pts) | M4: Gap at first check (pts) | N4: Gap on unit test (pts) | O4: Mastery % - C | P4: Mastery % - J | Q4: Gap C-J (pts)
A5: {=IFERROR(INDEX(CHECKS!$A$2:$A$2000,SMALL(IF(CHECKS!$E$2:$E$2000="y",ROW(CHECKS!$E$2:$E$2000)-1),1)),"")} -> W01 | B5: =IF(A5="","",INDEX(CHECKS!$C$2:$C$2000,MATCH(A5,CHECKS!$A$2:$A$2000,0))) -> MA.7.NSO.2.1 | C5: =IF(A5="","",SUMIFS(RECHECKS!$G$2:$G$2000,RECHECKS!$C$2:$C$2000,A5)) -> 42 | D5: =IF(OR(A5="",C5=0),"",SUMIFS(RECHECKS!$F$2:$F$2000,RECHECKS!$C$2:$C$2000,A5,RECHECKS!$G$2:$G$2000,1)/(5*C5)) -> 0.58095238 | E5: =IF(OR(A5="",C5=0),"",SUMIFS(RECHECKS!$D$2:$D$2000,RECHECKS!$C$2:$C$2000,A5,RECHECKS!$G$2:$G$2000,1)/(3*C5)) -> 0.82539683 | F5: =IF(D5="","",(E5-D5)*100) -> 24.444444 | G5: =IF(A5="","",INDEX(CHECKS!$F$2:$F$2000,MATCH(A5,CHECKS!$A$2:$A$2000,0))&"") | H5: =IF(OR(A5="",G5=""),"",SUMIFS(RECHECKS!$J$2:$J$2000,RECHECKS!$C$2:$C$2000,A5)) | I5: =IF(OR(H5="",H5=0),"",SUMIFS(RECHECKS!$I$2:$I$2000,RECHECKS!$C$2:$C$2000,A5,RECHECKS!$J$2:$J$2000,1)/(5*H5)) | J5: =IF(OR(H5="",H5=0),"",SUMIFS(RECHECKS!$E$2:$E$2000,RECHECKS!$C$2:$C$2000,A5,RECHECKS!$J$2:$J$2000,1)/(2*H5)) | K5: =IF(I5="","",(J5-I5)*100) | L5: =IF(F5="","",IF(K5="",F5,F5-K5)) -> 24.444444 | M5: =IF(A5="","",(SUMIFS(SCORES!$D$2:$D$2000,SCORES!$C$2:$C$2000,A5)/(5*COUNTIFS(SCORES!$C$2:$C$2000,A5,SCORES!$D$2:$D$2000,">=0"))-SUMIFS(SCORES!$D$2:$D$2000,SCORES!$D$2:$D$2000,">=0")/(5*COUNTIFS(SCORES!$D$2:$D$2000,">=0")))*100) -> 2.0679321 | N5: =IF(B5="","",IFERROR(INDEX(UNITS!$E$2:$E$2000,MATCH(B5,UNITS!$A$2:$A$2000,0)),"")) -> -3 | O5: =IF(A5="","",IFERROR(COUNTIFS(SCORES!$C$2:$C$2000,A5,SCORES!$B$2:$B$2000,"C",SCORES!$D$2:$D$2000,">=4")/COUNTIFS(SCORES!$C$2:$C$2000,A5,SCORES!$B$2:$B$2000,"C",SCORES!$D$2:$D$2000,">=0"),"")) -> 0.38095238 | P5: =IF(A5="","",IFERROR(COUNTIFS(SCORES!$C$2:$C$2000,A5,SCORES!$B$2:$B$2000,"J",SCORES!$D$2:$D$2000,">=4")/COUNTIFS(SCORES!$C$2:$C$2000,A5,SCORES!$B$2:$B$2000,"J",SCORES!$D$2:$D$2000,">=0"),"")) -> 0.34782609 | Q5: =IF(OR(O5="",P5=""),"",(O5-P5)*100) -> 3.3126294
A6: {=IFERROR(INDEX(CHECKS!$A$2:$A$2000,SMALL(IF(CHECKS!$E$2:$E$2000="y",ROW(CHECKS!$E$2:$E$2000)-1),2)),"")} -> W02 | B6: =IF(A6="","",INDEX(CHECKS!$C$2:$C$2000,MATCH(A6,CHECKS!$A$2:$A$2000,0))) -> MA.7.AR.1.1 | C6: =IF(A6="","",SUMIFS(RECHECKS!$G$2:$G$2000,RECHECKS!$C$2:$C$2000,A6)) -> 43 | D6: =IF(OR(A6="",C6=0),"",SUMIFS(RECHECKS!$F$2:$F$2000,RECHECKS!$C$2:$C$2000,A6,RECHECKS!$G$2:$G$2000,1)/(5*C6)) -> 0.51162791 | E6: =IF(OR(A6="",C6=0),"",SUMIFS(RECHECKS!$D$2:$D$2000,RECHECKS!$C$2:$C$2000,A6,RECHECKS!$G$2:$G$2000,1)/(3*C6)) -> 0.73643411 | F6: =IF(D6="","",(E6-D6)*100) -> 22.48062 | G6: =IF(A6="","",INDEX(CHECKS!$F$2:$F$2000,MATCH(A6,CHECKS!$A$2:$A$2000,0))&"") -> W01 | H6: =IF(OR(A6="",G6=""),"",SUMIFS(RECHECKS!$J$2:$J$2000,RECHECKS!$C$2:$C$2000,A6)) -> 42 | I6: =IF(OR(H6="",H6=0),"",SUMIFS(RECHECKS!$I$2:$I$2000,RECHECKS!$C$2:$C$2000,A6,RECHECKS!$J$2:$J$2000,1)/(5*H6)) -> 0.55714286 | J6: =IF(OR(H6="",H6=0),"",SUMIFS(RECHECKS!$E$2:$E$2000,RECHECKS!$C$2:$C$2000,A6,RECHECKS!$J$2:$J$2000,1)/(2*H6)) -> 0.60714286 | K6: =IF(I6="","",(J6-I6)*100) -> 5 | L6: =IF(F6="","",IF(K6="",F6,F6-K6)) -> 17.48062 | M6: =IF(A6="","",(SUMIFS(SCORES!$D$2:$D$2000,SCORES!$C$2:$C$2000,A6)/(5*COUNTIFS(SCORES!$C$2:$C$2000,A6,SCORES!$D$2:$D$2000,">=0"))-SUMIFS(SCORES!$D$2:$D$2000,SCORES!$D$2:$D$2000,">=0")/(5*COUNTIFS(SCORES!$D$2:$D$2000,">=0")))*100) -> -2.7704518 | N6: =IF(B6="","",IFERROR(INDEX(UNITS!$E$2:$E$2000,MATCH(B6,UNITS!$A$2:$A$2000,0)),"")) -> -8 | O6: =IF(A6="","",IFERROR(COUNTIFS(SCORES!$C$2:$C$2000,A6,SCORES!$B$2:$B$2000,"C",SCORES!$D$2:$D$2000,">=4")/COUNTIFS(SCORES!$C$2:$C$2000,A6,SCORES!$B$2:$B$2000,"C",SCORES!$D$2:$D$2000,">=0"),"")) -> 0.31818182 | P6: =IF(A6="","",IFERROR(COUNTIFS(SCORES!$C$2:$C$2000,A6,SCORES!$B$2:$B$2000,"J",SCORES!$D$2:$D$2000,">=4")/COUNTIFS(SCORES!$C$2:$C$2000,A6,SCORES!$B$2:$B$2000,"J",SCORES!$D$2:$D$2000,">=0"),"")) -> 0.30434783 | Q6: =IF(OR(O6="",P6=""),"",(O6-P6)*100) -> 1.3833992
A7: {=IFERROR(INDEX(CHECKS!$A$2:$A$2000,SMALL(IF(CHECKS!$E$2:$E$2000="y",ROW(CHECKS!$E$2:$E$2000)-1),3)),"")} -> W03 | B7: =IF(A7="","",INDEX(CHECKS!$C$2:$C$2000,MATCH(A7,CHECKS!$A$2:$A$2000,0))) -> MA.7.AR.1.2 | C7: =IF(A7="","",SUMIFS(RECHECKS!$G$2:$G$2000,RECHECKS!$C$2:$C$2000,A7)) -> 42 | D7: =IF(OR(A7="",C7=0),"",SUMIFS(RECHECKS!$F$2:$F$2000,RECHECKS!$C$2:$C$2000,A7,RECHECKS!$G$2:$G$2000,1)/(5*C7)) -> 0.66190476 | E7: =IF(OR(A7="",C7=0),"",SUMIFS(RECHECKS!$D$2:$D$2000,RECHECKS!$C$2:$C$2000,A7,RECHECKS!$G$2:$G$2000,1)/(3*C7)) -> 0.84126984 | F7: =IF(D7="","",(E7-D7)*100) -> 17.936508 | G7: =IF(A7="","",INDEX(CHECKS!$F$2:$F$2000,MATCH(A7,CHECKS!$A$2:$A$2000,0))&"") -> W02 | H7: =IF(OR(A7="",G7=""),"",SUMIFS(RECHECKS!$J$2:$J$2000,RECHECKS!$C$2:$C$2000,A7)) -> 40 | I7: =IF(OR(H7="",H7=0),"",SUMIFS(RECHECKS!$I$2:$I$2000,RECHECKS!$C$2:$C$2000,A7,RECHECKS!$J$2:$J$2000,1)/(5*H7)) -> 0.5 | J7: =IF(OR(H7="",H7=0),"",SUMIFS(RECHECKS!$E$2:$E$2000,RECHECKS!$C$2:$C$2000,A7,RECHECKS!$J$2:$J$2000,1)/(2*H7)) -> 0.4875 | K7: =IF(I7="","",(J7-I7)*100) -> -1.25 | L7: =IF(F7="","",IF(K7="",F7,F7-K7)) -> 19.186508 | M7: =IF(A7="","",(SUMIFS(SCORES!$D$2:$D$2000,SCORES!$C$2:$C$2000,A7)/(5*COUNTIFS(SCORES!$C$2:$C$2000,A7,SCORES!$D$2:$D$2000,">=0"))-SUMIFS(SCORES!$D$2:$D$2000,SCORES!$D$2:$D$2000,">=0")/(5*COUNTIFS(SCORES!$D$2:$D$2000,">=0")))*100) -> 7.6739927 | N7: =IF(B7="","",IFERROR(INDEX(UNITS!$E$2:$E$2000,MATCH(B7,UNITS!$A$2:$A$2000,0)),"")) -> -3 | O7: =IF(A7="","",IFERROR(COUNTIFS(SCORES!$C$2:$C$2000,A7,SCORES!$B$2:$B$2000,"C",SCORES!$D$2:$D$2000,">=4")/COUNTIFS(SCORES!$C$2:$C$2000,A7,SCORES!$B$2:$B$2000,"C",SCORES!$D$2:$D$2000,">=0"),"")) -> 0.41666667 | P7: =IF(A7="","",IFERROR(COUNTIFS(SCORES!$C$2:$C$2000,A7,SCORES!$B$2:$B$2000,"J",SCORES!$D$2:$D$2000,">=4")/COUNTIFS(SCORES!$C$2:$C$2000,A7,SCORES!$B$2:$B$2000,"J",SCORES!$D$2:$D$2000,">=0"),"")) -> 0.375 | Q7: =IF(OR(O7="",P7=""),"",(O7-P7)*100) -> 4.1666667
A8: {=IFERROR(INDEX(CHECKS!$A$2:$A$2000,SMALL(IF(CHECKS!$E$2:$E$2000="y",ROW(CHECKS!$E$2:$E$2000)-1),4)),"")} -> W04 | B8: =IF(A8="","",INDEX(CHECKS!$C$2:$C$2000,MATCH(A8,CHECKS!$A$2:$A$2000,0))) -> MA.7.AR.2.1 | C8: =IF(A8="","",SUMIFS(RECHECKS!$G$2:$G$2000,RECHECKS!$C$2:$C$2000,A8)) -> 45 | D8: =IF(OR(A8="",C8=0),"",SUMIFS(RECHECKS!$F$2:$F$2000,RECHECKS!$C$2:$C$2000,A8,RECHECKS!$G$2:$G$2000,1)/(5*C8)) -> 0.47111111 | E8: =IF(OR(A8="",C8=0),"",SUMIFS(RECHECKS!$D$2:$D$2000,RECHECKS!$C$2:$C$2000,A8,RECHECKS!$G$2:$G$2000,1)/(3*C8)) -> 0.61481481 | F8: =IF(D8="","",(E8-D8)*100) -> 14.37037 | G8: =IF(A8="","",INDEX(CHECKS!$F$2:$F$2000,MATCH(A8,CHECKS!$A$2:$A$2000,0))&"") -> W03 | H8: =IF(OR(A8="",G8=""),"",SUMIFS(RECHECKS!$J$2:$J$2000,RECHECKS!$C$2:$C$2000,A8)) -> 45 | I8: =IF(OR(H8="",H8=0),"",SUMIFS(RECHECKS!$I$2:$I$2000,RECHECKS!$C$2:$C$2000,A8,RECHECKS!$J$2:$J$2000,1)/(5*H8)) -> 0.63555556 | J8: =IF(OR(H8="",H8=0),"",SUMIFS(RECHECKS!$E$2:$E$2000,RECHECKS!$C$2:$C$2000,A8,RECHECKS!$J$2:$J$2000,1)/(2*H8)) -> 0.71111111 | K8: =IF(I8="","",(J8-I8)*100) -> 7.5555556 | L8: =IF(F8="","",IF(K8="",F8,F8-K8)) -> 6.8148148 | M8: =IF(A8="","",(SUMIFS(SCORES!$D$2:$D$2000,SCORES!$C$2:$C$2000,A8)/(5*COUNTIFS(SCORES!$C$2:$C$2000,A8,SCORES!$D$2:$D$2000,">=0"))-SUMIFS(SCORES!$D$2:$D$2000,SCORES!$D$2:$D$2000,">=0")/(5*COUNTIFS(SCORES!$D$2:$D$2000,">=0")))*100) -> -7.3260073 | N8: =IF(B8="","",IFERROR(INDEX(UNITS!$E$2:$E$2000,MATCH(B8,UNITS!$A$2:$A$2000,0)),"")) -> -10 | O8: =IF(A8="","",IFERROR(COUNTIFS(SCORES!$C$2:$C$2000,A8,SCORES!$B$2:$B$2000,"C",SCORES!$D$2:$D$2000,">=4")/COUNTIFS(SCORES!$C$2:$C$2000,A8,SCORES!$B$2:$B$2000,"C",SCORES!$D$2:$D$2000,">=0"),"")) -> 0.17391304 | P8: =IF(A8="","",IFERROR(COUNTIFS(SCORES!$C$2:$C$2000,A8,SCORES!$B$2:$B$2000,"J",SCORES!$D$2:$D$2000,">=4")/COUNTIFS(SCORES!$C$2:$C$2000,A8,SCORES!$B$2:$B$2000,"J",SCORES!$D$2:$D$2000,">=0"),"")) -> 0.16 | Q8: =IF(OR(O8="",P8=""),"",(O8-P8)*100) -> 1.3913043
A9: {=IFERROR(INDEX(CHECKS!$A$2:$A$2000,SMALL(IF(CHECKS!$E$2:$E$2000="y",ROW(CHECKS!$E$2:$E$2000)-1),5)),"")} -> W05 | B9: =IF(A9="","",INDEX(CHECKS!$C$2:$C$2000,MATCH(A9,CHECKS!$A$2:$A$2000,0))) -> MA.7.AR.3.1 | C9: =IF(A9="","",SUMIFS(RECHECKS!$G$2:$G$2000,RECHECKS!$C$2:$C$2000,A9)) -> 44 | D9: =IF(OR(A9="",C9=0),"",SUMIFS(RECHECKS!$F$2:$F$2000,RECHECKS!$C$2:$C$2000,A9,RECHECKS!$G$2:$G$2000,1)/(5*C9)) -> 0.61363636 | E9: =IF(OR(A9="",C9=0),"",SUMIFS(RECHECKS!$D$2:$D$2000,RECHECKS!$C$2:$C$2000,A9,RECHECKS!$G$2:$G$2000,1)/(3*C9)) -> 0.74242424 | F9: =IF(D9="","",(E9-D9)*100) -> 12.878788 | G9: =IF(A9="","",INDEX(CHECKS!$F$2:$F$2000,MATCH(A9,CHECKS!$A$2:$A$2000,0))&"") -> W04 | H9: =IF(OR(A9="",G9=""),"",SUMIFS(RECHECKS!$J$2:$J$2000,RECHECKS!$C$2:$C$2000,A9)) -> 47 | I9: =IF(OR(H9="",H9=0),"",SUMIFS(RECHECKS!$I$2:$I$2000,RECHECKS!$C$2:$C$2000,A9,RECHECKS!$J$2:$J$2000,1)/(5*H9)) -> 0.48085106 | J9: =IF(OR(H9="",H9=0),"",SUMIFS(RECHECKS!$E$2:$E$2000,RECHECKS!$C$2:$C$2000,A9,RECHECKS!$J$2:$J$2000,1)/(2*H9)) -> 0.42553191 | K9: =IF(I9="","",(J9-I9)*100) -> -5.5319149 | L9: =IF(F9="","",IF(K9="",F9,F9-K9)) -> 18.410703 | M9: =IF(A9="","",(SUMIFS(SCORES!$D$2:$D$2000,SCORES!$C$2:$C$2000,A9)/(5*COUNTIFS(SCORES!$C$2:$C$2000,A9,SCORES!$D$2:$D$2000,">=0"))-SUMIFS(SCORES!$D$2:$D$2000,SCORES!$D$2:$D$2000,">=0")/(5*COUNTIFS(SCORES!$D$2:$D$2000,">=0")))*100) -> 5.6450072 | N9: =IF(B9="","",IFERROR(INDEX(UNITS!$E$2:$E$2000,MATCH(B9,UNITS!$A$2:$A$2000,0)),"")) | O9: =IF(A9="","",IFERROR(COUNTIFS(SCORES!$C$2:$C$2000,A9,SCORES!$B$2:$B$2000,"C",SCORES!$D$2:$D$2000,">=4")/COUNTIFS(SCORES!$C$2:$C$2000,A9,SCORES!$B$2:$B$2000,"C",SCORES!$D$2:$D$2000,">=0"),"")) -> 0.39130435 | P9: =IF(A9="","",IFERROR(COUNTIFS(SCORES!$C$2:$C$2000,A9,SCORES!$B$2:$B$2000,"J",SCORES!$D$2:$D$2000,">=4")/COUNTIFS(SCORES!$C$2:$C$2000,A9,SCORES!$B$2:$B$2000,"J",SCORES!$D$2:$D$2000,">=0"),"")) -> 0.30434783 | Q9: =IF(OR(O9="",P9=""),"",(O9-P9)*100) -> 8.6956522
A10: {=IFERROR(INDEX(CHECKS!$A$2:$A$2000,SMALL(IF(CHECKS!$E$2:$E$2000="y",ROW(CHECKS!$E$2:$E$2000)-1),6)),"")} -> W06 | B10: =IF(A10="","",INDEX(CHECKS!$C$2:$C$2000,MATCH(A10,CHECKS!$A$2:$A$2000,0))) -> MA.7.AR.3.2 | C10: =IF(A10="","",SUMIFS(RECHECKS!$G$2:$G$2000,RECHECKS!$C$2:$C$2000,A10)) -> 40 | D10: =IF(OR(A10="",C10=0),"",SUMIFS(RECHECKS!$F$2:$F$2000,RECHECKS!$C$2:$C$2000,A10,RECHECKS!$G$2:$G$2000,1)/(5*C10)) -> 0.51 | E10: =IF(OR(A10="",C10=0),"",SUMIFS(RECHECKS!$D$2:$D$2000,RECHECKS!$C$2:$C$2000,A10,RECHECKS!$G$2:$G$2000,1)/(3*C10)) -> 0.80833333 | F10: =IF(D10="","",(E10-D10)*100) -> 29.833333 | G10: =IF(A10="","",INDEX(CHECKS!$F$2:$F$2000,MATCH(A10,CHECKS!$A$2:$A$2000,0))&"") -> W05 | H10: =IF(OR(A10="",G10=""),"",SUMIFS(RECHECKS!$J$2:$J$2000,RECHECKS!$C$2:$C$2000,A10)) -> 42 | I10: =IF(OR(H10="",H10=0),"",SUMIFS(RECHECKS!$I$2:$I$2000,RECHECKS!$C$2:$C$2000,A10,RECHECKS!$J$2:$J$2000,1)/(5*H10)) -> 0.63333333 | J10: =IF(OR(H10="",H10=0),"",SUMIFS(RECHECKS!$E$2:$E$2000,RECHECKS!$C$2:$C$2000,A10,RECHECKS!$J$2:$J$2000,1)/(2*H10)) -> 0.45238095 | K10: =IF(I10="","",(J10-I10)*100) -> -18.095238 | L10: =IF(F10="","",IF(K10="",F10,F10-K10)) -> 47.928571 | M10: =IF(A10="","",(SUMIFS(SCORES!$D$2:$D$2000,SCORES!$C$2:$C$2000,A10)/(5*COUNTIFS(SCORES!$C$2:$C$2000,A10,SCORES!$D$2:$D$2000,">=0"))-SUMIFS(SCORES!$D$2:$D$2000,SCORES!$D$2:$D$2000,">=0")/(5*COUNTIFS(SCORES!$D$2:$D$2000,">=0")))*100) -> -7.9320679 | N10: =IF(B10="","",IFERROR(INDEX(UNITS!$E$2:$E$2000,MATCH(B10,UNITS!$A$2:$A$2000,0)),"")) | O10: =IF(A10="","",IFERROR(COUNTIFS(SCORES!$C$2:$C$2000,A10,SCORES!$B$2:$B$2000,"C",SCORES!$D$2:$D$2000,">=4")/COUNTIFS(SCORES!$C$2:$C$2000,A10,SCORES!$B$2:$B$2000,"C",SCORES!$D$2:$D$2000,">=0"),"")) -> 0.26086957 | P10: =IF(A10="","",IFERROR(COUNTIFS(SCORES!$C$2:$C$2000,A10,SCORES!$B$2:$B$2000,"J",SCORES!$D$2:$D$2000,">=4")/COUNTIFS(SCORES!$C$2:$C$2000,A10,SCORES!$B$2:$B$2000,"J",SCORES!$D$2:$D$2000,">=0"),"")) -> 0.19047619 | Q10: =IF(OR(O10="",P10=""),"",(O10-P10)*100) -> 7.0393375
A11: {=IFERROR(INDEX(CHECKS!$A$2:$A$2000,SMALL(IF(CHECKS!$E$2:$E$2000="y",ROW(CHECKS!$E$2:$E$2000)-1),7)),"")} | B11: =IF(A11="","",INDEX(CHECKS!$C$2:$C$2000,MATCH(A11,CHECKS!$A$2:$A$2000,0))) | C11: =IF(A11="","",SUMIFS(RECHECKS!$G$2:$G$2000,RECHECKS!$C$2:$C$2000,A11)) | D11: =IF(OR(A11="",C11=0),"",SUMIFS(RECHECKS!$F$2:$F$2000,RECHECKS!$C$2:$C$2000,A11,RECHECKS!$G$2:$G$2000,1)/(5*C11)) | E11: =IF(OR(A11="",C11=0),"",SUMIFS(RECHECKS!$D$2:$D$2000,RECHECKS!$C$2:$C$2000,A11,RECHECKS!$G$2:$G$2000,1)/(3*C11)) | F11: =IF(D11="","",(E11-D11)*100) | G11: =IF(A11="","",INDEX(CHECKS!$F$2:$F$2000,MATCH(A11,CHECKS!$A$2:$A$2000,0))&"") | H11: =IF(OR(A11="",G11=""),"",SUMIFS(RECHECKS!$J$2:$J$2000,RECHECKS!$C$2:$C$2000,A11)) | I11: =IF(OR(H11="",H11=0),"",SUMIFS(RECHECKS!$I$2:$I$2000,RECHECKS!$C$2:$C$2000,A11,RECHECKS!$J$2:$J$2000,1)/(5*H11)) | J11: =IF(OR(H11="",H11=0),"",SUMIFS(RECHECKS!$E$2:$E$2000,RECHECKS!$C$2:$C$2000,A11,RECHECKS!$J$2:$J$2000,1)/(2*H11)) | K11: =IF(I11="","",(J11-I11)*100) | L11: =IF(F11="","",IF(K11="",F11,F11-K11)) | M11: =IF(A11="","",(SUMIFS(SCORES!$D$2:$D$2000,SCORES!$C$2:$C$2000,A11)/(5*COUNTIFS(SCORES!$C$2:$C$2000,A11,SCORES!$D$2:$D$2000,">=0"))-SUMIFS(SCORES!$D$2:$D$2000,SCORES!$D$2:$D$2000,">=0")/(5*COUNTIFS(SCORES!$D$2:$D$2000,">=0")))*100) | N11: =IF(B11="","",IFERROR(INDEX(UNITS!$E$2:$E$2000,MATCH(B11,UNITS!$A$2:$A$2000,0)),"")) | O11: =IF(A11="","",IFERROR(COUNTIFS(SCORES!$C$2:$C$2000,A11,SCORES!$B$2:$B$2000,"C",SCORES!$D$2:$D$2000,">=4")/COUNTIFS(SCORES!$C$2:$C$2000,A11,SCORES!$B$2:$B$2000,"C",SCORES!$D$2:$D$2000,">=0"),"")) | P11: =IF(A11="","",IFERROR(COUNTIFS(SCORES!$C$2:$C$2000,A11,SCORES!$B$2:$B$2000,"J",SCORES!$D$2:$D$2000,">=4")/COUNTIFS(SCORES!$C$2:$C$2000,A11,SCORES!$B$2:$B$2000,"J",SCORES!$D$2:$D$2000,">=0"),"")) | Q11: =IF(OR(O11="",P11=""),"",(O11-P11)*100)
A12: {=IFERROR(INDEX(CHECKS!$A$2:$A$2000,SMALL(IF(CHECKS!$E$2:$E$2000="y",ROW(CHECKS!$E$2:$E$2000)-1),8)),"")} | B12: =IF(A12="","",INDEX(CHECKS!$C$2:$C$2000,MATCH(A12,CHECKS!$A$2:$A$2000,0))) | C12: =IF(A12="","",SUMIFS(RECHECKS!$G$2:$G$2000,RECHECKS!$C$2:$C$2000,A12)) | D12: =IF(OR(A12="",C12=0),"",SUMIFS(RECHECKS!$F$2:$F$2000,RECHECKS!$C$2:$C$2000,A12,RECHECKS!$G$2:$G$2000,1)/(5*C12)) | E12: =IF(OR(A12="",C12=0),"",SUMIFS(RECHECKS!$D$2:$D$2000,RECHECKS!$C$2:$C$2000,A12,RECHECKS!$G$2:$G$2000,1)/(3*C12)) | F12: =IF(D12="","",(E12-D12)*100) | G12: =IF(A12="","",INDEX(CHECKS!$F$2:$F$2000,MATCH(A12,CHECKS!$A$2:$A$2000,0))&"") | H12: =IF(OR(A12="",G12=""),"",SUMIFS(RECHECKS!$J$2:$J$2000,RECHECKS!$C$2:$C$2000,A12)) | I12: =IF(OR(H12="",H12=0),"",SUMIFS(RECHECKS!$I$2:$I$2000,RECHECKS!$C$2:$C$2000,A12,RECHECKS!$J$2:$J$2000,1)/(5*H12)) | J12: =IF(OR(H12="",H12=0),"",SUMIFS(RECHECKS!$E$2:$E$2000,RECHECKS!$C$2:$C$2000,A12,RECHECKS!$J$2:$J$2000,1)/(2*H12)) | K12: =IF(I12="","",(J12-I12)*100) | L12: =IF(F12="","",IF(K12="",F12,F12-K12)) | M12: =IF(A12="","",(SUMIFS(SCORES!$D$2:$D$2000,SCORES!$C$2:$C$2000,A12)/(5*COUNTIFS(SCORES!$C$2:$C$2000,A12,SCORES!$D$2:$D$2000,">=0"))-SUMIFS(SCORES!$D$2:$D$2000,SCORES!$D$2:$D$2000,">=0")/(5*COUNTIFS(SCORES!$D$2:$D$2000,">=0")))*100) | N12: =IF(B12="","",IFERROR(INDEX(UNITS!$E$2:$E$2000,MATCH(B12,UNITS!$A$2:$A$2000,0)),"")) | O12: =IF(A12="","",IFERROR(COUNTIFS(SCORES!$C$2:$C$2000,A12,SCORES!$B$2:$B$2000,"C",SCORES!$D$2:$D$2000,">=4")/COUNTIFS(SCORES!$C$2:$C$2000,A12,SCORES!$B$2:$B$2000,"C",SCORES!$D$2:$D$2000,">=0"),"")) | P12: =IF(A12="","",IFERROR(COUNTIFS(SCORES!$C$2:$C$2000,A12,SCORES!$B$2:$B$2000,"J",SCORES!$D$2:$D$2000,">=4")/COUNTIFS(SCORES!$C$2:$C$2000,A12,SCORES!$B$2:$B$2000,"J",SCORES!$D$2:$D$2000,">=0"),"")) | Q12: =IF(OR(O12="",P12=""),"",(O12-P12)*100)
A13: {=IFERROR(INDEX(CHECKS!$A$2:$A$2000,SMALL(IF(CHECKS!$E$2:$E$2000="y",ROW(CHECKS!$E$2:$E$2000)-1),9)),"")} | B13: =IF(A13="","",INDEX(CHECKS!$C$2:$C$2000,MATCH(A13,CHECKS!$A$2:$A$2000,0))) | C13: =IF(A13="","",SUMIFS(RECHECKS!$G$2:$G$2000,RECHECKS!$C$2:$C$2000,A13)) | D13: =IF(OR(A13="",C13=0),"",SUMIFS(RECHECKS!$F$2:$F$2000,RECHECKS!$C$2:$C$2000,A13,RECHECKS!$G$2:$G$2000,1)/(5*C13)) | E13: =IF(OR(A13="",C13=0),"",SUMIFS(RECHECKS!$D$2:$D$2000,RECHECKS!$C$2:$C$2000,A13,RECHECKS!$G$2:$G$2000,1)/(3*C13)) | F13: =IF(D13="","",(E13-D13)*100) | G13: =IF(A13="","",INDEX(CHECKS!$F$2:$F$2000,MATCH(A13,CHECKS!$A$2:$A$2000,0))&"") | H13: =IF(OR(A13="",G13=""),"",SUMIFS(RECHECKS!$J$2:$J$2000,RECHECKS!$C$2:$C$2000,A13)) | I13: =IF(OR(H13="",H13=0),"",SUMIFS(RECHECKS!$I$2:$I$2000,RECHECKS!$C$2:$C$2000,A13,RECHECKS!$J$2:$J$2000,1)/(5*H13)) | J13: =IF(OR(H13="",H13=0),"",SUMIFS(RECHECKS!$E$2:$E$2000,RECHECKS!$C$2:$C$2000,A13,RECHECKS!$J$2:$J$2000,1)/(2*H13)) | K13: =IF(I13="","",(J13-I13)*100) | L13: =IF(F13="","",IF(K13="",F13,F13-K13)) | M13: =IF(A13="","",(SUMIFS(SCORES!$D$2:$D$2000,SCORES!$C$2:$C$2000,A13)/(5*COUNTIFS(SCORES!$C$2:$C$2000,A13,SCORES!$D$2:$D$2000,">=0"))-SUMIFS(SCORES!$D$2:$D$2000,SCORES!$D$2:$D$2000,">=0")/(5*COUNTIFS(SCORES!$D$2:$D$2000,">=0")))*100) | N13: =IF(B13="","",IFERROR(INDEX(UNITS!$E$2:$E$2000,MATCH(B13,UNITS!$A$2:$A$2000,0)),"")) | O13: =IF(A13="","",IFERROR(COUNTIFS(SCORES!$C$2:$C$2000,A13,SCORES!$B$2:$B$2000,"C",SCORES!$D$2:$D$2000,">=4")/COUNTIFS(SCORES!$C$2:$C$2000,A13,SCORES!$B$2:$B$2000,"C",SCORES!$D$2:$D$2000,">=0"),"")) | P13: =IF(A13="","",IFERROR(COUNTIFS(SCORES!$C$2:$C$2000,A13,SCORES!$B$2:$B$2000,"J",SCORES!$D$2:$D$2000,">=4")/COUNTIFS(SCORES!$C$2:$C$2000,A13,SCORES!$B$2:$B$2000,"J",SCORES!$D$2:$D$2000,">=0"),"")) | Q13: =IF(OR(O13="",P13=""),"",(O13-P13)*100)
A14: {=IFERROR(INDEX(CHECKS!$A$2:$A$2000,SMALL(IF(CHECKS!$E$2:$E$2000="y",ROW(CHECKS!$E$2:$E$2000)-1),10)),"")} | B14: =IF(A14="","",INDEX(CHECKS!$C$2:$C$2000,MATCH(A14,CHECKS!$A$2:$A$2000,0))) | C14: =IF(A14="","",SUMIFS(RECHECKS!$G$2:$G$2000,RECHECKS!$C$2:$C$2000,A14)) | D14: =IF(OR(A14="",C14=0),"",SUMIFS(RECHECKS!$F$2:$F$2000,RECHECKS!$C$2:$C$2000,A14,RECHECKS!$G$2:$G$2000,1)/(5*C14)) | E14: =IF(OR(A14="",C14=0),"",SUMIFS(RECHECKS!$D$2:$D$2000,RECHECKS!$C$2:$C$2000,A14,RECHECKS!$G$2:$G$2000,1)/(3*C14)) | F14: =IF(D14="","",(E14-D14)*100) | G14: =IF(A14="","",INDEX(CHECKS!$F$2:$F$2000,MATCH(A14,CHECKS!$A$2:$A$2000,0))&"") | H14: =IF(OR(A14="",G14=""),"",SUMIFS(RECHECKS!$J$2:$J$2000,RECHECKS!$C$2:$C$2000,A14)) | I14: =IF(OR(H14="",H14=0),"",SUMIFS(RECHECKS!$I$2:$I$2000,RECHECKS!$C$2:$C$2000,A14,RECHECKS!$J$2:$J$2000,1)/(5*H14)) | J14: =IF(OR(H14="",H14=0),"",SUMIFS(RECHECKS!$E$2:$E$2000,RECHECKS!$C$2:$C$2000,A14,RECHECKS!$J$2:$J$2000,1)/(2*H14)) | K14: =IF(I14="","",(J14-I14)*100) | L14: =IF(F14="","",IF(K14="",F14,F14-K14)) | M14: =IF(A14="","",(SUMIFS(SCORES!$D$2:$D$2000,SCORES!$C$2:$C$2000,A14)/(5*COUNTIFS(SCORES!$C$2:$C$2000,A14,SCORES!$D$2:$D$2000,">=0"))-SUMIFS(SCORES!$D$2:$D$2000,SCORES!$D$2:$D$2000,">=0")/(5*COUNTIFS(SCORES!$D$2:$D$2000,">=0")))*100) | N14: =IF(B14="","",IFERROR(INDEX(UNITS!$E$2:$E$2000,MATCH(B14,UNITS!$A$2:$A$2000,0)),"")) | O14: =IF(A14="","",IFERROR(COUNTIFS(SCORES!$C$2:$C$2000,A14,SCORES!$B$2:$B$2000,"C",SCORES!$D$2:$D$2000,">=4")/COUNTIFS(SCORES!$C$2:$C$2000,A14,SCORES!$B$2:$B$2000,"C",SCORES!$D$2:$D$2000,">=0"),"")) | P14: =IF(A14="","",IFERROR(COUNTIFS(SCORES!$C$2:$C$2000,A14,SCORES!$B$2:$B$2000,"J",SCORES!$D$2:$D$2000,">=4")/COUNTIFS(SCORES!$C$2:$C$2000,A14,SCORES!$B$2:$B$2000,"J",SCORES!$D$2:$D$2000,">=0"),"")) | Q14: =IF(OR(O14="",P14=""),"",(O14-P14)*100)
A15: {=IFERROR(INDEX(CHECKS!$A$2:$A$2000,SMALL(IF(CHECKS!$E$2:$E$2000="y",ROW(CHECKS!$E$2:$E$2000)-1),11)),"")} | B15: =IF(A15="","",INDEX(CHECKS!$C$2:$C$2000,MATCH(A15,CHECKS!$A$2:$A$2000,0))) | C15: =IF(A15="","",SUMIFS(RECHECKS!$G$2:$G$2000,RECHECKS!$C$2:$C$2000,A15)) | D15: =IF(OR(A15="",C15=0),"",SUMIFS(RECHECKS!$F$2:$F$2000,RECHECKS!$C$2:$C$2000,A15,RECHECKS!$G$2:$G$2000,1)/(5*C15)) | E15: =IF(OR(A15="",C15=0),"",SUMIFS(RECHECKS!$D$2:$D$2000,RECHECKS!$C$2:$C$2000,A15,RECHECKS!$G$2:$G$2000,1)/(3*C15)) | F15: =IF(D15="","",(E15-D15)*100) | G15: =IF(A15="","",INDEX(CHECKS!$F$2:$F$2000,MATCH(A15,CHECKS!$A$2:$A$2000,0))&"") | H15: =IF(OR(A15="",G15=""),"",SUMIFS(RECHECKS!$J$2:$J$2000,RECHECKS!$C$2:$C$2000,A15)) | I15: =IF(OR(H15="",H15=0),"",SUMIFS(RECHECKS!$I$2:$I$2000,RECHECKS!$C$2:$C$2000,A15,RECHECKS!$J$2:$J$2000,1)/(5*H15)) | J15: =IF(OR(H15="",H15=0),"",SUMIFS(RECHECKS!$E$2:$E$2000,RECHECKS!$C$2:$C$2000,A15,RECHECKS!$J$2:$J$2000,1)/(2*H15)) | K15: =IF(I15="","",(J15-I15)*100) | L15: =IF(F15="","",IF(K15="",F15,F15-K15)) | M15: =IF(A15="","",(SUMIFS(SCORES!$D$2:$D$2000,SCORES!$C$2:$C$2000,A15)/(5*COUNTIFS(SCORES!$C$2:$C$2000,A15,SCORES!$D$2:$D$2000,">=0"))-SUMIFS(SCORES!$D$2:$D$2000,SCORES!$D$2:$D$2000,">=0")/(5*COUNTIFS(SCORES!$D$2:$D$2000,">=0")))*100) | N15: =IF(B15="","",IFERROR(INDEX(UNITS!$E$2:$E$2000,MATCH(B15,UNITS!$A$2:$A$2000,0)),"")) | O15: =IF(A15="","",IFERROR(COUNTIFS(SCORES!$C$2:$C$2000,A15,SCORES!$B$2:$B$2000,"C",SCORES!$D$2:$D$2000,">=4")/COUNTIFS(SCORES!$C$2:$C$2000,A15,SCORES!$B$2:$B$2000,"C",SCORES!$D$2:$D$2000,">=0"),"")) | P15: =IF(A15="","",IFERROR(COUNTIFS(SCORES!$C$2:$C$2000,A15,SCORES!$B$2:$B$2000,"J",SCORES!$D$2:$D$2000,">=4")/COUNTIFS(SCORES!$C$2:$C$2000,A15,SCORES!$B$2:$B$2000,"J",SCORES!$D$2:$D$2000,">=0"),"")) | Q15: =IF(OR(O15="",P15=""),"",(O15-P15)*100)
A16: {=IFERROR(INDEX(CHECKS!$A$2:$A$2000,SMALL(IF(CHECKS!$E$2:$E$2000="y",ROW(CHECKS!$E$2:$E$2000)-1),12)),"")} | B16: =IF(A16="","",INDEX(CHECKS!$C$2:$C$2000,MATCH(A16,CHECKS!$A$2:$A$2000,0))) | C16: =IF(A16="","",SUMIFS(RECHECKS!$G$2:$G$2000,RECHECKS!$C$2:$C$2000,A16)) | D16: =IF(OR(A16="",C16=0),"",SUMIFS(RECHECKS!$F$2:$F$2000,RECHECKS!$C$2:$C$2000,A16,RECHECKS!$G$2:$G$2000,1)/(5*C16)) | E16: =IF(OR(A16="",C16=0),"",SUMIFS(RECHECKS!$D$2:$D$2000,RECHECKS!$C$2:$C$2000,A16,RECHECKS!$G$2:$G$2000,1)/(3*C16)) | F16: =IF(D16="","",(E16-D16)*100) | G16: =IF(A16="","",INDEX(CHECKS!$F$2:$F$2000,MATCH(A16,CHECKS!$A$2:$A$2000,0))&"") | H16: =IF(OR(A16="",G16=""),"",SUMIFS(RECHECKS!$J$2:$J$2000,RECHECKS!$C$2:$C$2000,A16)) | I16: =IF(OR(H16="",H16=0),"",SUMIFS(RECHECKS!$I$2:$I$2000,RECHECKS!$C$2:$C$2000,A16,RECHECKS!$J$2:$J$2000,1)/(5*H16)) | J16: =IF(OR(H16="",H16=0),"",SUMIFS(RECHECKS!$E$2:$E$2000,RECHECKS!$C$2:$C$2000,A16,RECHECKS!$J$2:$J$2000,1)/(2*H16)) | K16: =IF(I16="","",(J16-I16)*100) | L16: =IF(F16="","",IF(K16="",F16,F16-K16)) | M16: =IF(A16="","",(SUMIFS(SCORES!$D$2:$D$2000,SCORES!$C$2:$C$2000,A16)/(5*COUNTIFS(SCORES!$C$2:$C$2000,A16,SCORES!$D$2:$D$2000,">=0"))-SUMIFS(SCORES!$D$2:$D$2000,SCORES!$D$2:$D$2000,">=0")/(5*COUNTIFS(SCORES!$D$2:$D$2000,">=0")))*100) | N16: =IF(B16="","",IFERROR(INDEX(UNITS!$E$2:$E$2000,MATCH(B16,UNITS!$A$2:$A$2000,0)),"")) | O16: =IF(A16="","",IFERROR(COUNTIFS(SCORES!$C$2:$C$2000,A16,SCORES!$B$2:$B$2000,"C",SCORES!$D$2:$D$2000,">=4")/COUNTIFS(SCORES!$C$2:$C$2000,A16,SCORES!$B$2:$B$2000,"C",SCORES!$D$2:$D$2000,">=0"),"")) | P16: =IF(A16="","",IFERROR(COUNTIFS(SCORES!$C$2:$C$2000,A16,SCORES!$B$2:$B$2000,"J",SCORES!$D$2:$D$2000,">=4")/COUNTIFS(SCORES!$C$2:$C$2000,A16,SCORES!$B$2:$B$2000,"J",SCORES!$D$2:$D$2000,">=0"),"")) | Q16: =IF(OR(O16="",P16=""),"",(O16-P16)*100)
A17: {=IFERROR(INDEX(CHECKS!$A$2:$A$2000,SMALL(IF(CHECKS!$E$2:$E$2000="y",ROW(CHECKS!$E$2:$E$2000)-1),13)),"")} | B17: =IF(A17="","",INDEX(CHECKS!$C$2:$C$2000,MATCH(A17,CHECKS!$A$2:$A$2000,0))) | C17: =IF(A17="","",SUMIFS(RECHECKS!$G$2:$G$2000,RECHECKS!$C$2:$C$2000,A17)) | D17: =IF(OR(A17="",C17=0),"",SUMIFS(RECHECKS!$F$2:$F$2000,RECHECKS!$C$2:$C$2000,A17,RECHECKS!$G$2:$G$2000,1)/(5*C17)) | E17: =IF(OR(A17="",C17=0),"",SUMIFS(RECHECKS!$D$2:$D$2000,RECHECKS!$C$2:$C$2000,A17,RECHECKS!$G$2:$G$2000,1)/(3*C17)) | F17: =IF(D17="","",(E17-D17)*100) | G17: =IF(A17="","",INDEX(CHECKS!$F$2:$F$2000,MATCH(A17,CHECKS!$A$2:$A$2000,0))&"") | H17: =IF(OR(A17="",G17=""),"",SUMIFS(RECHECKS!$J$2:$J$2000,RECHECKS!$C$2:$C$2000,A17)) | I17: =IF(OR(H17="",H17=0),"",SUMIFS(RECHECKS!$I$2:$I$2000,RECHECKS!$C$2:$C$2000,A17,RECHECKS!$J$2:$J$2000,1)/(5*H17)) | J17: =IF(OR(H17="",H17=0),"",SUMIFS(RECHECKS!$E$2:$E$2000,RECHECKS!$C$2:$C$2000,A17,RECHECKS!$J$2:$J$2000,1)/(2*H17)) | K17: =IF(I17="","",(J17-I17)*100) | L17: =IF(F17="","",IF(K17="",F17,F17-K17)) | M17: =IF(A17="","",(SUMIFS(SCORES!$D$2:$D$2000,SCORES!$C$2:$C$2000,A17)/(5*COUNTIFS(SCORES!$C$2:$C$2000,A17,SCORES!$D$2:$D$2000,">=0"))-SUMIFS(SCORES!$D$2:$D$2000,SCORES!$D$2:$D$2000,">=0")/(5*COUNTIFS(SCORES!$D$2:$D$2000,">=0")))*100) | N17: =IF(B17="","",IFERROR(INDEX(UNITS!$E$2:$E$2000,MATCH(B17,UNITS!$A$2:$A$2000,0)),"")) | O17: =IF(A17="","",IFERROR(COUNTIFS(SCORES!$C$2:$C$2000,A17,SCORES!$B$2:$B$2000,"C",SCORES!$D$2:$D$2000,">=4")/COUNTIFS(SCORES!$C$2:$C$2000,A17,SCORES!$B$2:$B$2000,"C",SCORES!$D$2:$D$2000,">=0"),"")) | P17: =IF(A17="","",IFERROR(COUNTIFS(SCORES!$C$2:$C$2000,A17,SCORES!$B$2:$B$2000,"J",SCORES!$D$2:$D$2000,">=4")/COUNTIFS(SCORES!$C$2:$C$2000,A17,SCORES!$B$2:$B$2000,"J",SCORES!$D$2:$D$2000,">=0"),"")) | Q17: =IF(OR(O17="",P17=""),"",(O17-P17)*100)
A18: {=IFERROR(INDEX(CHECKS!$A$2:$A$2000,SMALL(IF(CHECKS!$E$2:$E$2000="y",ROW(CHECKS!$E$2:$E$2000)-1),14)),"")} | B18: =IF(A18="","",INDEX(CHECKS!$C$2:$C$2000,MATCH(A18,CHECKS!$A$2:$A$2000,0))) | C18: =IF(A18="","",SUMIFS(RECHECKS!$G$2:$G$2000,RECHECKS!$C$2:$C$2000,A18)) | D18: =IF(OR(A18="",C18=0),"",SUMIFS(RECHECKS!$F$2:$F$2000,RECHECKS!$C$2:$C$2000,A18,RECHECKS!$G$2:$G$2000,1)/(5*C18)) | E18: =IF(OR(A18="",C18=0),"",SUMIFS(RECHECKS!$D$2:$D$2000,RECHECKS!$C$2:$C$2000,A18,RECHECKS!$G$2:$G$2000,1)/(3*C18)) | F18: =IF(D18="","",(E18-D18)*100) | G18: =IF(A18="","",INDEX(CHECKS!$F$2:$F$2000,MATCH(A18,CHECKS!$A$2:$A$2000,0))&"") | H18: =IF(OR(A18="",G18=""),"",SUMIFS(RECHECKS!$J$2:$J$2000,RECHECKS!$C$2:$C$2000,A18)) | I18: =IF(OR(H18="",H18=0),"",SUMIFS(RECHECKS!$I$2:$I$2000,RECHECKS!$C$2:$C$2000,A18,RECHECKS!$J$2:$J$2000,1)/(5*H18)) | J18: =IF(OR(H18="",H18=0),"",SUMIFS(RECHECKS!$E$2:$E$2000,RECHECKS!$C$2:$C$2000,A18,RECHECKS!$J$2:$J$2000,1)/(2*H18)) | K18: =IF(I18="","",(J18-I18)*100) | L18: =IF(F18="","",IF(K18="",F18,F18-K18)) | M18: =IF(A18="","",(SUMIFS(SCORES!$D$2:$D$2000,SCORES!$C$2:$C$2000,A18)/(5*COUNTIFS(SCORES!$C$2:$C$2000,A18,SCORES!$D$2:$D$2000,">=0"))-SUMIFS(SCORES!$D$2:$D$2000,SCORES!$D$2:$D$2000,">=0")/(5*COUNTIFS(SCORES!$D$2:$D$2000,">=0")))*100) | N18: =IF(B18="","",IFERROR(INDEX(UNITS!$E$2:$E$2000,MATCH(B18,UNITS!$A$2:$A$2000,0)),"")) | O18: =IF(A18="","",IFERROR(COUNTIFS(SCORES!$C$2:$C$2000,A18,SCORES!$B$2:$B$2000,"C",SCORES!$D$2:$D$2000,">=4")/COUNTIFS(SCORES!$C$2:$C$2000,A18,SCORES!$B$2:$B$2000,"C",SCORES!$D$2:$D$2000,">=0"),"")) | P18: =IF(A18="","",IFERROR(COUNTIFS(SCORES!$C$2:$C$2000,A18,SCORES!$B$2:$B$2000,"J",SCORES!$D$2:$D$2000,">=4")/COUNTIFS(SCORES!$C$2:$C$2000,A18,SCORES!$B$2:$B$2000,"J",SCORES!$D$2:$D$2000,">=0"),"")) | Q18: =IF(OR(O18="",P18=""),"",(O18-P18)*100)
A19: {=IFERROR(INDEX(CHECKS!$A$2:$A$2000,SMALL(IF(CHECKS!$E$2:$E$2000="y",ROW(CHECKS!$E$2:$E$2000)-1),15)),"")} | B19: =IF(A19="","",INDEX(CHECKS!$C$2:$C$2000,MATCH(A19,CHECKS!$A$2:$A$2000,0))) | C19: =IF(A19="","",SUMIFS(RECHECKS!$G$2:$G$2000,RECHECKS!$C$2:$C$2000,A19)) | D19: =IF(OR(A19="",C19=0),"",SUMIFS(RECHECKS!$F$2:$F$2000,RECHECKS!$C$2:$C$2000,A19,RECHECKS!$G$2:$G$2000,1)/(5*C19)) | E19: =IF(OR(A19="",C19=0),"",SUMIFS(RECHECKS!$D$2:$D$2000,RECHECKS!$C$2:$C$2000,A19,RECHECKS!$G$2:$G$2000,1)/(3*C19)) | F19: =IF(D19="","",(E19-D19)*100) | G19: =IF(A19="","",INDEX(CHECKS!$F$2:$F$2000,MATCH(A19,CHECKS!$A$2:$A$2000,0))&"") | H19: =IF(OR(A19="",G19=""),"",SUMIFS(RECHECKS!$J$2:$J$2000,RECHECKS!$C$2:$C$2000,A19)) | I19: =IF(OR(H19="",H19=0),"",SUMIFS(RECHECKS!$I$2:$I$2000,RECHECKS!$C$2:$C$2000,A19,RECHECKS!$J$2:$J$2000,1)/(5*H19)) | J19: =IF(OR(H19="",H19=0),"",SUMIFS(RECHECKS!$E$2:$E$2000,RECHECKS!$C$2:$C$2000,A19,RECHECKS!$J$2:$J$2000,1)/(2*H19)) | K19: =IF(I19="","",(J19-I19)*100) | L19: =IF(F19="","",IF(K19="",F19,F19-K19)) | M19: =IF(A19="","",(SUMIFS(SCORES!$D$2:$D$2000,SCORES!$C$2:$C$2000,A19)/(5*COUNTIFS(SCORES!$C$2:$C$2000,A19,SCORES!$D$2:$D$2000,">=0"))-SUMIFS(SCORES!$D$2:$D$2000,SCORES!$D$2:$D$2000,">=0")/(5*COUNTIFS(SCORES!$D$2:$D$2000,">=0")))*100) | N19: =IF(B19="","",IFERROR(INDEX(UNITS!$E$2:$E$2000,MATCH(B19,UNITS!$A$2:$A$2000,0)),"")) | O19: =IF(A19="","",IFERROR(COUNTIFS(SCORES!$C$2:$C$2000,A19,SCORES!$B$2:$B$2000,"C",SCORES!$D$2:$D$2000,">=4")/COUNTIFS(SCORES!$C$2:$C$2000,A19,SCORES!$B$2:$B$2000,"C",SCORES!$D$2:$D$2000,">=0"),"")) | P19: =IF(A19="","",IFERROR(COUNTIFS(SCORES!$C$2:$C$2000,A19,SCORES!$B$2:$B$2000,"J",SCORES!$D$2:$D$2000,">=4")/COUNTIFS(SCORES!$C$2:$C$2000,A19,SCORES!$B$2:$B$2000,"J",SCORES!$D$2:$D$2000,">=0"),"")) | Q19: =IF(OR(O19="",P19=""),"",(O19-P19)*100)
A20: {=IFERROR(INDEX(CHECKS!$A$2:$A$2000,SMALL(IF(CHECKS!$E$2:$E$2000="y",ROW(CHECKS!$E$2:$E$2000)-1),16)),"")} | B20: =IF(A20="","",INDEX(CHECKS!$C$2:$C$2000,MATCH(A20,CHECKS!$A$2:$A$2000,0))) | C20: =IF(A20="","",SUMIFS(RECHECKS!$G$2:$G$2000,RECHECKS!$C$2:$C$2000,A20)) | D20: =IF(OR(A20="",C20=0),"",SUMIFS(RECHECKS!$F$2:$F$2000,RECHECKS!$C$2:$C$2000,A20,RECHECKS!$G$2:$G$2000,1)/(5*C20)) | E20: =IF(OR(A20="",C20=0),"",SUMIFS(RECHECKS!$D$2:$D$2000,RECHECKS!$C$2:$C$2000,A20,RECHECKS!$G$2:$G$2000,1)/(3*C20)) | F20: =IF(D20="","",(E20-D20)*100) | G20: =IF(A20="","",INDEX(CHECKS!$F$2:$F$2000,MATCH(A20,CHECKS!$A$2:$A$2000,0))&"") | H20: =IF(OR(A20="",G20=""),"",SUMIFS(RECHECKS!$J$2:$J$2000,RECHECKS!$C$2:$C$2000,A20)) | I20: =IF(OR(H20="",H20=0),"",SUMIFS(RECHECKS!$I$2:$I$2000,RECHECKS!$C$2:$C$2000,A20,RECHECKS!$J$2:$J$2000,1)/(5*H20)) | J20: =IF(OR(H20="",H20=0),"",SUMIFS(RECHECKS!$E$2:$E$2000,RECHECKS!$C$2:$C$2000,A20,RECHECKS!$J$2:$J$2000,1)/(2*H20)) | K20: =IF(I20="","",(J20-I20)*100) | L20: =IF(F20="","",IF(K20="",F20,F20-K20)) | M20: =IF(A20="","",(SUMIFS(SCORES!$D$2:$D$2000,SCORES!$C$2:$C$2000,A20)/(5*COUNTIFS(SCORES!$C$2:$C$2000,A20,SCORES!$D$2:$D$2000,">=0"))-SUMIFS(SCORES!$D$2:$D$2000,SCORES!$D$2:$D$2000,">=0")/(5*COUNTIFS(SCORES!$D$2:$D$2000,">=0")))*100) | N20: =IF(B20="","",IFERROR(INDEX(UNITS!$E$2:$E$2000,MATCH(B20,UNITS!$A$2:$A$2000,0)),"")) | O20: =IF(A20="","",IFERROR(COUNTIFS(SCORES!$C$2:$C$2000,A20,SCORES!$B$2:$B$2000,"C",SCORES!$D$2:$D$2000,">=4")/COUNTIFS(SCORES!$C$2:$C$2000,A20,SCORES!$B$2:$B$2000,"C",SCORES!$D$2:$D$2000,">=0"),"")) | P20: =IF(A20="","",IFERROR(COUNTIFS(SCORES!$C$2:$C$2000,A20,SCORES!$B$2:$B$2000,"J",SCORES!$D$2:$D$2000,">=4")/COUNTIFS(SCORES!$C$2:$C$2000,A20,SCORES!$B$2:$B$2000,"J",SCORES!$D$2:$D$2000,">=0"),"")) | Q20: =IF(OR(O20="",P20=""),"",(O20-P20)*100)
A21: {=IFERROR(INDEX(CHECKS!$A$2:$A$2000,SMALL(IF(CHECKS!$E$2:$E$2000="y",ROW(CHECKS!$E$2:$E$2000)-1),17)),"")} | B21: =IF(A21="","",INDEX(CHECKS!$C$2:$C$2000,MATCH(A21,CHECKS!$A$2:$A$2000,0))) | C21: =IF(A21="","",SUMIFS(RECHECKS!$G$2:$G$2000,RECHECKS!$C$2:$C$2000,A21)) | D21: =IF(OR(A21="",C21=0),"",SUMIFS(RECHECKS!$F$2:$F$2000,RECHECKS!$C$2:$C$2000,A21,RECHECKS!$G$2:$G$2000,1)/(5*C21)) | E21: =IF(OR(A21="",C21=0),"",SUMIFS(RECHECKS!$D$2:$D$2000,RECHECKS!$C$2:$C$2000,A21,RECHECKS!$G$2:$G$2000,1)/(3*C21)) | F21: =IF(D21="","",(E21-D21)*100) | G21: =IF(A21="","",INDEX(CHECKS!$F$2:$F$2000,MATCH(A21,CHECKS!$A$2:$A$2000,0))&"") | H21: =IF(OR(A21="",G21=""),"",SUMIFS(RECHECKS!$J$2:$J$2000,RECHECKS!$C$2:$C$2000,A21)) | I21: =IF(OR(H21="",H21=0),"",SUMIFS(RECHECKS!$I$2:$I$2000,RECHECKS!$C$2:$C$2000,A21,RECHECKS!$J$2:$J$2000,1)/(5*H21)) | J21: =IF(OR(H21="",H21=0),"",SUMIFS(RECHECKS!$E$2:$E$2000,RECHECKS!$C$2:$C$2000,A21,RECHECKS!$J$2:$J$2000,1)/(2*H21)) | K21: =IF(I21="","",(J21-I21)*100) | L21: =IF(F21="","",IF(K21="",F21,F21-K21)) | M21: =IF(A21="","",(SUMIFS(SCORES!$D$2:$D$2000,SCORES!$C$2:$C$2000,A21)/(5*COUNTIFS(SCORES!$C$2:$C$2000,A21,SCORES!$D$2:$D$2000,">=0"))-SUMIFS(SCORES!$D$2:$D$2000,SCORES!$D$2:$D$2000,">=0")/(5*COUNTIFS(SCORES!$D$2:$D$2000,">=0")))*100) | N21: =IF(B21="","",IFERROR(INDEX(UNITS!$E$2:$E$2000,MATCH(B21,UNITS!$A$2:$A$2000,0)),"")) | O21: =IF(A21="","",IFERROR(COUNTIFS(SCORES!$C$2:$C$2000,A21,SCORES!$B$2:$B$2000,"C",SCORES!$D$2:$D$2000,">=4")/COUNTIFS(SCORES!$C$2:$C$2000,A21,SCORES!$B$2:$B$2000,"C",SCORES!$D$2:$D$2000,">=0"),"")) | P21: =IF(A21="","",IFERROR(COUNTIFS(SCORES!$C$2:$C$2000,A21,SCORES!$B$2:$B$2000,"J",SCORES!$D$2:$D$2000,">=4")/COUNTIFS(SCORES!$C$2:$C$2000,A21,SCORES!$B$2:$B$2000,"J",SCORES!$D$2:$D$2000,">=0"),"")) | Q21: =IF(OR(O21="",P21=""),"",(O21-P21)*100)
A22: {=IFERROR(INDEX(CHECKS!$A$2:$A$2000,SMALL(IF(CHECKS!$E$2:$E$2000="y",ROW(CHECKS!$E$2:$E$2000)-1),18)),"")} | B22: =IF(A22="","",INDEX(CHECKS!$C$2:$C$2000,MATCH(A22,CHECKS!$A$2:$A$2000,0))) | C22: =IF(A22="","",SUMIFS(RECHECKS!$G$2:$G$2000,RECHECKS!$C$2:$C$2000,A22)) | D22: =IF(OR(A22="",C22=0),"",SUMIFS(RECHECKS!$F$2:$F$2000,RECHECKS!$C$2:$C$2000,A22,RECHECKS!$G$2:$G$2000,1)/(5*C22)) | E22: =IF(OR(A22="",C22=0),"",SUMIFS(RECHECKS!$D$2:$D$2000,RECHECKS!$C$2:$C$2000,A22,RECHECKS!$G$2:$G$2000,1)/(3*C22)) | F22: =IF(D22="","",(E22-D22)*100) | G22: =IF(A22="","",INDEX(CHECKS!$F$2:$F$2000,MATCH(A22,CHECKS!$A$2:$A$2000,0))&"") | H22: =IF(OR(A22="",G22=""),"",SUMIFS(RECHECKS!$J$2:$J$2000,RECHECKS!$C$2:$C$2000,A22)) | I22: =IF(OR(H22="",H22=0),"",SUMIFS(RECHECKS!$I$2:$I$2000,RECHECKS!$C$2:$C$2000,A22,RECHECKS!$J$2:$J$2000,1)/(5*H22)) | J22: =IF(OR(H22="",H22=0),"",SUMIFS(RECHECKS!$E$2:$E$2000,RECHECKS!$C$2:$C$2000,A22,RECHECKS!$J$2:$J$2000,1)/(2*H22)) | K22: =IF(I22="","",(J22-I22)*100) | L22: =IF(F22="","",IF(K22="",F22,F22-K22)) | M22: =IF(A22="","",(SUMIFS(SCORES!$D$2:$D$2000,SCORES!$C$2:$C$2000,A22)/(5*COUNTIFS(SCORES!$C$2:$C$2000,A22,SCORES!$D$2:$D$2000,">=0"))-SUMIFS(SCORES!$D$2:$D$2000,SCORES!$D$2:$D$2000,">=0")/(5*COUNTIFS(SCORES!$D$2:$D$2000,">=0")))*100) | N22: =IF(B22="","",IFERROR(INDEX(UNITS!$E$2:$E$2000,MATCH(B22,UNITS!$A$2:$A$2000,0)),"")) | O22: =IF(A22="","",IFERROR(COUNTIFS(SCORES!$C$2:$C$2000,A22,SCORES!$B$2:$B$2000,"C",SCORES!$D$2:$D$2000,">=4")/COUNTIFS(SCORES!$C$2:$C$2000,A22,SCORES!$B$2:$B$2000,"C",SCORES!$D$2:$D$2000,">=0"),"")) | P22: =IF(A22="","",IFERROR(COUNTIFS(SCORES!$C$2:$C$2000,A22,SCORES!$B$2:$B$2000,"J",SCORES!$D$2:$D$2000,">=4")/COUNTIFS(SCORES!$C$2:$C$2000,A22,SCORES!$B$2:$B$2000,"J",SCORES!$D$2:$D$2000,">=0"),"")) | Q22: =IF(OR(O22="",P22=""),"",(O22-P22)*100)
A23: {=IFERROR(INDEX(CHECKS!$A$2:$A$2000,SMALL(IF(CHECKS!$E$2:$E$2000="y",ROW(CHECKS!$E$2:$E$2000)-1),19)),"")} | B23: =IF(A23="","",INDEX(CHECKS!$C$2:$C$2000,MATCH(A23,CHECKS!$A$2:$A$2000,0))) | C23: =IF(A23="","",SUMIFS(RECHECKS!$G$2:$G$2000,RECHECKS!$C$2:$C$2000,A23)) | D23: =IF(OR(A23="",C23=0),"",SUMIFS(RECHECKS!$F$2:$F$2000,RECHECKS!$C$2:$C$2000,A23,RECHECKS!$G$2:$G$2000,1)/(5*C23)) | E23: =IF(OR(A23="",C23=0),"",SUMIFS(RECHECKS!$D$2:$D$2000,RECHECKS!$C$2:$C$2000,A23,RECHECKS!$G$2:$G$2000,1)/(3*C23)) | F23: =IF(D23="","",(E23-D23)*100) | G23: =IF(A23="","",INDEX(CHECKS!$F$2:$F$2000,MATCH(A23,CHECKS!$A$2:$A$2000,0))&"") | H23: =IF(OR(A23="",G23=""),"",SUMIFS(RECHECKS!$J$2:$J$2000,RECHECKS!$C$2:$C$2000,A23)) | I23: =IF(OR(H23="",H23=0),"",SUMIFS(RECHECKS!$I$2:$I$2000,RECHECKS!$C$2:$C$2000,A23,RECHECKS!$J$2:$J$2000,1)/(5*H23)) | J23: =IF(OR(H23="",H23=0),"",SUMIFS(RECHECKS!$E$2:$E$2000,RECHECKS!$C$2:$C$2000,A23,RECHECKS!$J$2:$J$2000,1)/(2*H23)) | K23: =IF(I23="","",(J23-I23)*100) | L23: =IF(F23="","",IF(K23="",F23,F23-K23)) | M23: =IF(A23="","",(SUMIFS(SCORES!$D$2:$D$2000,SCORES!$C$2:$C$2000,A23)/(5*COUNTIFS(SCORES!$C$2:$C$2000,A23,SCORES!$D$2:$D$2000,">=0"))-SUMIFS(SCORES!$D$2:$D$2000,SCORES!$D$2:$D$2000,">=0")/(5*COUNTIFS(SCORES!$D$2:$D$2000,">=0")))*100) | N23: =IF(B23="","",IFERROR(INDEX(UNITS!$E$2:$E$2000,MATCH(B23,UNITS!$A$2:$A$2000,0)),"")) | O23: =IF(A23="","",IFERROR(COUNTIFS(SCORES!$C$2:$C$2000,A23,SCORES!$B$2:$B$2000,"C",SCORES!$D$2:$D$2000,">=4")/COUNTIFS(SCORES!$C$2:$C$2000,A23,SCORES!$B$2:$B$2000,"C",SCORES!$D$2:$D$2000,">=0"),"")) | P23: =IF(A23="","",IFERROR(COUNTIFS(SCORES!$C$2:$C$2000,A23,SCORES!$B$2:$B$2000,"J",SCORES!$D$2:$D$2000,">=4")/COUNTIFS(SCORES!$C$2:$C$2000,A23,SCORES!$B$2:$B$2000,"J",SCORES!$D$2:$D$2000,">=0"),"")) | Q23: =IF(OR(O23="",P23=""),"",(O23-P23)*100)
A24: {=IFERROR(INDEX(CHECKS!$A$2:$A$2000,SMALL(IF(CHECKS!$E$2:$E$2000="y",ROW(CHECKS!$E$2:$E$2000)-1),20)),"")} | B24: =IF(A24="","",INDEX(CHECKS!$C$2:$C$2000,MATCH(A24,CHECKS!$A$2:$A$2000,0))) | C24: =IF(A24="","",SUMIFS(RECHECKS!$G$2:$G$2000,RECHECKS!$C$2:$C$2000,A24)) | D24: =IF(OR(A24="",C24=0),"",SUMIFS(RECHECKS!$F$2:$F$2000,RECHECKS!$C$2:$C$2000,A24,RECHECKS!$G$2:$G$2000,1)/(5*C24)) | E24: =IF(OR(A24="",C24=0),"",SUMIFS(RECHECKS!$D$2:$D$2000,RECHECKS!$C$2:$C$2000,A24,RECHECKS!$G$2:$G$2000,1)/(3*C24)) | F24: =IF(D24="","",(E24-D24)*100) | G24: =IF(A24="","",INDEX(CHECKS!$F$2:$F$2000,MATCH(A24,CHECKS!$A$2:$A$2000,0))&"") | H24: =IF(OR(A24="",G24=""),"",SUMIFS(RECHECKS!$J$2:$J$2000,RECHECKS!$C$2:$C$2000,A24)) | I24: =IF(OR(H24="",H24=0),"",SUMIFS(RECHECKS!$I$2:$I$2000,RECHECKS!$C$2:$C$2000,A24,RECHECKS!$J$2:$J$2000,1)/(5*H24)) | J24: =IF(OR(H24="",H24=0),"",SUMIFS(RECHECKS!$E$2:$E$2000,RECHECKS!$C$2:$C$2000,A24,RECHECKS!$J$2:$J$2000,1)/(2*H24)) | K24: =IF(I24="","",(J24-I24)*100) | L24: =IF(F24="","",IF(K24="",F24,F24-K24)) | M24: =IF(A24="","",(SUMIFS(SCORES!$D$2:$D$2000,SCORES!$C$2:$C$2000,A24)/(5*COUNTIFS(SCORES!$C$2:$C$2000,A24,SCORES!$D$2:$D$2000,">=0"))-SUMIFS(SCORES!$D$2:$D$2000,SCORES!$D$2:$D$2000,">=0")/(5*COUNTIFS(SCORES!$D$2:$D$2000,">=0")))*100) | N24: =IF(B24="","",IFERROR(INDEX(UNITS!$E$2:$E$2000,MATCH(B24,UNITS!$A$2:$A$2000,0)),"")) | O24: =IF(A24="","",IFERROR(COUNTIFS(SCORES!$C$2:$C$2000,A24,SCORES!$B$2:$B$2000,"C",SCORES!$D$2:$D$2000,">=4")/COUNTIFS(SCORES!$C$2:$C$2000,A24,SCORES!$B$2:$B$2000,"C",SCORES!$D$2:$D$2000,">=0"),"")) | P24: =IF(A24="","",IFERROR(COUNTIFS(SCORES!$C$2:$C$2000,A24,SCORES!$B$2:$B$2000,"J",SCORES!$D$2:$D$2000,">=4")/COUNTIFS(SCORES!$C$2:$C$2000,A24,SCORES!$B$2:$B$2000,"J",SCORES!$D$2:$D$2000,">=0"),"")) | Q24: =IF(OR(O24="",P24=""),"",(O24-P24)*100)
A25: {=IFERROR(INDEX(CHECKS!$A$2:$A$2000,SMALL(IF(CHECKS!$E$2:$E$2000="y",ROW(CHECKS!$E$2:$E$2000)-1),21)),"")} | B25: =IF(A25="","",INDEX(CHECKS!$C$2:$C$2000,MATCH(A25,CHECKS!$A$2:$A$2000,0))) | C25: =IF(A25="","",SUMIFS(RECHECKS!$G$2:$G$2000,RECHECKS!$C$2:$C$2000,A25)) | D25: =IF(OR(A25="",C25=0),"",SUMIFS(RECHECKS!$F$2:$F$2000,RECHECKS!$C$2:$C$2000,A25,RECHECKS!$G$2:$G$2000,1)/(5*C25)) | E25: =IF(OR(A25="",C25=0),"",SUMIFS(RECHECKS!$D$2:$D$2000,RECHECKS!$C$2:$C$2000,A25,RECHECKS!$G$2:$G$2000,1)/(3*C25)) | F25: =IF(D25="","",(E25-D25)*100) | G25: =IF(A25="","",INDEX(CHECKS!$F$2:$F$2000,MATCH(A25,CHECKS!$A$2:$A$2000,0))&"") | H25: =IF(OR(A25="",G25=""),"",SUMIFS(RECHECKS!$J$2:$J$2000,RECHECKS!$C$2:$C$2000,A25)) | I25: =IF(OR(H25="",H25=0),"",SUMIFS(RECHECKS!$I$2:$I$2000,RECHECKS!$C$2:$C$2000,A25,RECHECKS!$J$2:$J$2000,1)/(5*H25)) | J25: =IF(OR(H25="",H25=0),"",SUMIFS(RECHECKS!$E$2:$E$2000,RECHECKS!$C$2:$C$2000,A25,RECHECKS!$J$2:$J$2000,1)/(2*H25)) | K25: =IF(I25="","",(J25-I25)*100) | L25: =IF(F25="","",IF(K25="",F25,F25-K25)) | M25: =IF(A25="","",(SUMIFS(SCORES!$D$2:$D$2000,SCORES!$C$2:$C$2000,A25)/(5*COUNTIFS(SCORES!$C$2:$C$2000,A25,SCORES!$D$2:$D$2000,">=0"))-SUMIFS(SCORES!$D$2:$D$2000,SCORES!$D$2:$D$2000,">=0")/(5*COUNTIFS(SCORES!$D$2:$D$2000,">=0")))*100) | N25: =IF(B25="","",IFERROR(INDEX(UNITS!$E$2:$E$2000,MATCH(B25,UNITS!$A$2:$A$2000,0)),"")) | O25: =IF(A25="","",IFERROR(COUNTIFS(SCORES!$C$2:$C$2000,A25,SCORES!$B$2:$B$2000,"C",SCORES!$D$2:$D$2000,">=4")/COUNTIFS(SCORES!$C$2:$C$2000,A25,SCORES!$B$2:$B$2000,"C",SCORES!$D$2:$D$2000,">=0"),"")) | P25: =IF(A25="","",IFERROR(COUNTIFS(SCORES!$C$2:$C$2000,A25,SCORES!$B$2:$B$2000,"J",SCORES!$D$2:$D$2000,">=4")/COUNTIFS(SCORES!$C$2:$C$2000,A25,SCORES!$B$2:$B$2000,"J",SCORES!$D$2:$D$2000,">=0"),"")) | Q25: =IF(OR(O25="",P25=""),"",(O25-P25)*100)
A26: {=IFERROR(INDEX(CHECKS!$A$2:$A$2000,SMALL(IF(CHECKS!$E$2:$E$2000="y",ROW(CHECKS!$E$2:$E$2000)-1),22)),"")} | B26: =IF(A26="","",INDEX(CHECKS!$C$2:$C$2000,MATCH(A26,CHECKS!$A$2:$A$2000,0))) | C26: =IF(A26="","",SUMIFS(RECHECKS!$G$2:$G$2000,RECHECKS!$C$2:$C$2000,A26)) | D26: =IF(OR(A26="",C26=0),"",SUMIFS(RECHECKS!$F$2:$F$2000,RECHECKS!$C$2:$C$2000,A26,RECHECKS!$G$2:$G$2000,1)/(5*C26)) | E26: =IF(OR(A26="",C26=0),"",SUMIFS(RECHECKS!$D$2:$D$2000,RECHECKS!$C$2:$C$2000,A26,RECHECKS!$G$2:$G$2000,1)/(3*C26)) | F26: =IF(D26="","",(E26-D26)*100) | G26: =IF(A26="","",INDEX(CHECKS!$F$2:$F$2000,MATCH(A26,CHECKS!$A$2:$A$2000,0))&"") | H26: =IF(OR(A26="",G26=""),"",SUMIFS(RECHECKS!$J$2:$J$2000,RECHECKS!$C$2:$C$2000,A26)) | I26: =IF(OR(H26="",H26=0),"",SUMIFS(RECHECKS!$I$2:$I$2000,RECHECKS!$C$2:$C$2000,A26,RECHECKS!$J$2:$J$2000,1)/(5*H26)) | J26: =IF(OR(H26="",H26=0),"",SUMIFS(RECHECKS!$E$2:$E$2000,RECHECKS!$C$2:$C$2000,A26,RECHECKS!$J$2:$J$2000,1)/(2*H26)) | K26: =IF(I26="","",(J26-I26)*100) | L26: =IF(F26="","",IF(K26="",F26,F26-K26)) | M26: =IF(A26="","",(SUMIFS(SCORES!$D$2:$D$2000,SCORES!$C$2:$C$2000,A26)/(5*COUNTIFS(SCORES!$C$2:$C$2000,A26,SCORES!$D$2:$D$2000,">=0"))-SUMIFS(SCORES!$D$2:$D$2000,SCORES!$D$2:$D$2000,">=0")/(5*COUNTIFS(SCORES!$D$2:$D$2000,">=0")))*100) | N26: =IF(B26="","",IFERROR(INDEX(UNITS!$E$2:$E$2000,MATCH(B26,UNITS!$A$2:$A$2000,0)),"")) | O26: =IF(A26="","",IFERROR(COUNTIFS(SCORES!$C$2:$C$2000,A26,SCORES!$B$2:$B$2000,"C",SCORES!$D$2:$D$2000,">=4")/COUNTIFS(SCORES!$C$2:$C$2000,A26,SCORES!$B$2:$B$2000,"C",SCORES!$D$2:$D$2000,">=0"),"")) | P26: =IF(A26="","",IFERROR(COUNTIFS(SCORES!$C$2:$C$2000,A26,SCORES!$B$2:$B$2000,"J",SCORES!$D$2:$D$2000,">=4")/COUNTIFS(SCORES!$C$2:$C$2000,A26,SCORES!$B$2:$B$2000,"J",SCORES!$D$2:$D$2000,">=0"),"")) | Q26: =IF(OR(O26="",P26=""),"",(O26-P26)*100)
A27: {=IFERROR(INDEX(CHECKS!$A$2:$A$2000,SMALL(IF(CHECKS!$E$2:$E$2000="y",ROW(CHECKS!$E$2:$E$2000)-1),23)),"")} | B27: =IF(A27="","",INDEX(CHECKS!$C$2:$C$2000,MATCH(A27,CHECKS!$A$2:$A$2000,0))) | C27: =IF(A27="","",SUMIFS(RECHECKS!$G$2:$G$2000,RECHECKS!$C$2:$C$2000,A27)) | D27: =IF(OR(A27="",C27=0),"",SUMIFS(RECHECKS!$F$2:$F$2000,RECHECKS!$C$2:$C$2000,A27,RECHECKS!$G$2:$G$2000,1)/(5*C27)) | E27: =IF(OR(A27="",C27=0),"",SUMIFS(RECHECKS!$D$2:$D$2000,RECHECKS!$C$2:$C$2000,A27,RECHECKS!$G$2:$G$2000,1)/(3*C27)) | F27: =IF(D27="","",(E27-D27)*100) | G27: =IF(A27="","",INDEX(CHECKS!$F$2:$F$2000,MATCH(A27,CHECKS!$A$2:$A$2000,0))&"") | H27: =IF(OR(A27="",G27=""),"",SUMIFS(RECHECKS!$J$2:$J$2000,RECHECKS!$C$2:$C$2000,A27)) | I27: =IF(OR(H27="",H27=0),"",SUMIFS(RECHECKS!$I$2:$I$2000,RECHECKS!$C$2:$C$2000,A27,RECHECKS!$J$2:$J$2000,1)/(5*H27)) | J27: =IF(OR(H27="",H27=0),"",SUMIFS(RECHECKS!$E$2:$E$2000,RECHECKS!$C$2:$C$2000,A27,RECHECKS!$J$2:$J$2000,1)/(2*H27)) | K27: =IF(I27="","",(J27-I27)*100) | L27: =IF(F27="","",IF(K27="",F27,F27-K27)) | M27: =IF(A27="","",(SUMIFS(SCORES!$D$2:$D$2000,SCORES!$C$2:$C$2000,A27)/(5*COUNTIFS(SCORES!$C$2:$C$2000,A27,SCORES!$D$2:$D$2000,">=0"))-SUMIFS(SCORES!$D$2:$D$2000,SCORES!$D$2:$D$2000,">=0")/(5*COUNTIFS(SCORES!$D$2:$D$2000,">=0")))*100) | N27: =IF(B27="","",IFERROR(INDEX(UNITS!$E$2:$E$2000,MATCH(B27,UNITS!$A$2:$A$2000,0)),"")) | O27: =IF(A27="","",IFERROR(COUNTIFS(SCORES!$C$2:$C$2000,A27,SCORES!$B$2:$B$2000,"C",SCORES!$D$2:$D$2000,">=4")/COUNTIFS(SCORES!$C$2:$C$2000,A27,SCORES!$B$2:$B$2000,"C",SCORES!$D$2:$D$2000,">=0"),"")) | P27: =IF(A27="","",IFERROR(COUNTIFS(SCORES!$C$2:$C$2000,A27,SCORES!$B$2:$B$2000,"J",SCORES!$D$2:$D$2000,">=4")/COUNTIFS(SCORES!$C$2:$C$2000,A27,SCORES!$B$2:$B$2000,"J",SCORES!$D$2:$D$2000,">=0"),"")) | Q27: =IF(OR(O27="",P27=""),"",(O27-P27)*100)
A28: {=IFERROR(INDEX(CHECKS!$A$2:$A$2000,SMALL(IF(CHECKS!$E$2:$E$2000="y",ROW(CHECKS!$E$2:$E$2000)-1),24)),"")} | B28: =IF(A28="","",INDEX(CHECKS!$C$2:$C$2000,MATCH(A28,CHECKS!$A$2:$A$2000,0))) | C28: =IF(A28="","",SUMIFS(RECHECKS!$G$2:$G$2000,RECHECKS!$C$2:$C$2000,A28)) | D28: =IF(OR(A28="",C28=0),"",SUMIFS(RECHECKS!$F$2:$F$2000,RECHECKS!$C$2:$C$2000,A28,RECHECKS!$G$2:$G$2000,1)/(5*C28)) | E28: =IF(OR(A28="",C28=0),"",SUMIFS(RECHECKS!$D$2:$D$2000,RECHECKS!$C$2:$C$2000,A28,RECHECKS!$G$2:$G$2000,1)/(3*C28)) | F28: =IF(D28="","",(E28-D28)*100) | G28: =IF(A28="","",INDEX(CHECKS!$F$2:$F$2000,MATCH(A28,CHECKS!$A$2:$A$2000,0))&"") | H28: =IF(OR(A28="",G28=""),"",SUMIFS(RECHECKS!$J$2:$J$2000,RECHECKS!$C$2:$C$2000,A28)) | I28: =IF(OR(H28="",H28=0),"",SUMIFS(RECHECKS!$I$2:$I$2000,RECHECKS!$C$2:$C$2000,A28,RECHECKS!$J$2:$J$2000,1)/(5*H28)) | J28: =IF(OR(H28="",H28=0),"",SUMIFS(RECHECKS!$E$2:$E$2000,RECHECKS!$C$2:$C$2000,A28,RECHECKS!$J$2:$J$2000,1)/(2*H28)) | K28: =IF(I28="","",(J28-I28)*100) | L28: =IF(F28="","",IF(K28="",F28,F28-K28)) | M28: =IF(A28="","",(SUMIFS(SCORES!$D$2:$D$2000,SCORES!$C$2:$C$2000,A28)/(5*COUNTIFS(SCORES!$C$2:$C$2000,A28,SCORES!$D$2:$D$2000,">=0"))-SUMIFS(SCORES!$D$2:$D$2000,SCORES!$D$2:$D$2000,">=0")/(5*COUNTIFS(SCORES!$D$2:$D$2000,">=0")))*100) | N28: =IF(B28="","",IFERROR(INDEX(UNITS!$E$2:$E$2000,MATCH(B28,UNITS!$A$2:$A$2000,0)),"")) | O28: =IF(A28="","",IFERROR(COUNTIFS(SCORES!$C$2:$C$2000,A28,SCORES!$B$2:$B$2000,"C",SCORES!$D$2:$D$2000,">=4")/COUNTIFS(SCORES!$C$2:$C$2000,A28,SCORES!$B$2:$B$2000,"C",SCORES!$D$2:$D$2000,">=0"),"")) | P28: =IF(A28="","",IFERROR(COUNTIFS(SCORES!$C$2:$C$2000,A28,SCORES!$B$2:$B$2000,"J",SCORES!$D$2:$D$2000,">=4")/COUNTIFS(SCORES!$C$2:$C$2000,A28,SCORES!$B$2:$B$2000,"J",SCORES!$D$2:$D$2000,">=0"),"")) | Q28: =IF(OR(O28="",P28=""),"",(O28-P28)*100)
A29: {=IFERROR(INDEX(CHECKS!$A$2:$A$2000,SMALL(IF(CHECKS!$E$2:$E$2000="y",ROW(CHECKS!$E$2:$E$2000)-1),25)),"")} | B29: =IF(A29="","",INDEX(CHECKS!$C$2:$C$2000,MATCH(A29,CHECKS!$A$2:$A$2000,0))) | C29: =IF(A29="","",SUMIFS(RECHECKS!$G$2:$G$2000,RECHECKS!$C$2:$C$2000,A29)) | D29: =IF(OR(A29="",C29=0),"",SUMIFS(RECHECKS!$F$2:$F$2000,RECHECKS!$C$2:$C$2000,A29,RECHECKS!$G$2:$G$2000,1)/(5*C29)) | E29: =IF(OR(A29="",C29=0),"",SUMIFS(RECHECKS!$D$2:$D$2000,RECHECKS!$C$2:$C$2000,A29,RECHECKS!$G$2:$G$2000,1)/(3*C29)) | F29: =IF(D29="","",(E29-D29)*100) | G29: =IF(A29="","",INDEX(CHECKS!$F$2:$F$2000,MATCH(A29,CHECKS!$A$2:$A$2000,0))&"") | H29: =IF(OR(A29="",G29=""),"",SUMIFS(RECHECKS!$J$2:$J$2000,RECHECKS!$C$2:$C$2000,A29)) | I29: =IF(OR(H29="",H29=0),"",SUMIFS(RECHECKS!$I$2:$I$2000,RECHECKS!$C$2:$C$2000,A29,RECHECKS!$J$2:$J$2000,1)/(5*H29)) | J29: =IF(OR(H29="",H29=0),"",SUMIFS(RECHECKS!$E$2:$E$2000,RECHECKS!$C$2:$C$2000,A29,RECHECKS!$J$2:$J$2000,1)/(2*H29)) | K29: =IF(I29="","",(J29-I29)*100) | L29: =IF(F29="","",IF(K29="",F29,F29-K29)) | M29: =IF(A29="","",(SUMIFS(SCORES!$D$2:$D$2000,SCORES!$C$2:$C$2000,A29)/(5*COUNTIFS(SCORES!$C$2:$C$2000,A29,SCORES!$D$2:$D$2000,">=0"))-SUMIFS(SCORES!$D$2:$D$2000,SCORES!$D$2:$D$2000,">=0")/(5*COUNTIFS(SCORES!$D$2:$D$2000,">=0")))*100) | N29: =IF(B29="","",IFERROR(INDEX(UNITS!$E$2:$E$2000,MATCH(B29,UNITS!$A$2:$A$2000,0)),"")) | O29: =IF(A29="","",IFERROR(COUNTIFS(SCORES!$C$2:$C$2000,A29,SCORES!$B$2:$B$2000,"C",SCORES!$D$2:$D$2000,">=4")/COUNTIFS(SCORES!$C$2:$C$2000,A29,SCORES!$B$2:$B$2000,"C",SCORES!$D$2:$D$2000,">=0"),"")) | P29: =IF(A29="","",IFERROR(COUNTIFS(SCORES!$C$2:$C$2000,A29,SCORES!$B$2:$B$2000,"J",SCORES!$D$2:$D$2000,">=4")/COUNTIFS(SCORES!$C$2:$C$2000,A29,SCORES!$B$2:$B$2000,"J",SCORES!$D$2:$D$2000,">=0"),"")) | Q29: =IF(OR(O29="",P29=""),"",(O29-P29)*100)
A30: {=IFERROR(INDEX(CHECKS!$A$2:$A$2000,SMALL(IF(CHECKS!$E$2:$E$2000="y",ROW(CHECKS!$E$2:$E$2000)-1),26)),"")} | B30: =IF(A30="","",INDEX(CHECKS!$C$2:$C$2000,MATCH(A30,CHECKS!$A$2:$A$2000,0))) | C30: =IF(A30="","",SUMIFS(RECHECKS!$G$2:$G$2000,RECHECKS!$C$2:$C$2000,A30)) | D30: =IF(OR(A30="",C30=0),"",SUMIFS(RECHECKS!$F$2:$F$2000,RECHECKS!$C$2:$C$2000,A30,RECHECKS!$G$2:$G$2000,1)/(5*C30)) | E30: =IF(OR(A30="",C30=0),"",SUMIFS(RECHECKS!$D$2:$D$2000,RECHECKS!$C$2:$C$2000,A30,RECHECKS!$G$2:$G$2000,1)/(3*C30)) | F30: =IF(D30="","",(E30-D30)*100) | G30: =IF(A30="","",INDEX(CHECKS!$F$2:$F$2000,MATCH(A30,CHECKS!$A$2:$A$2000,0))&"") | H30: =IF(OR(A30="",G30=""),"",SUMIFS(RECHECKS!$J$2:$J$2000,RECHECKS!$C$2:$C$2000,A30)) | I30: =IF(OR(H30="",H30=0),"",SUMIFS(RECHECKS!$I$2:$I$2000,RECHECKS!$C$2:$C$2000,A30,RECHECKS!$J$2:$J$2000,1)/(5*H30)) | J30: =IF(OR(H30="",H30=0),"",SUMIFS(RECHECKS!$E$2:$E$2000,RECHECKS!$C$2:$C$2000,A30,RECHECKS!$J$2:$J$2000,1)/(2*H30)) | K30: =IF(I30="","",(J30-I30)*100) | L30: =IF(F30="","",IF(K30="",F30,F30-K30)) | M30: =IF(A30="","",(SUMIFS(SCORES!$D$2:$D$2000,SCORES!$C$2:$C$2000,A30)/(5*COUNTIFS(SCORES!$C$2:$C$2000,A30,SCORES!$D$2:$D$2000,">=0"))-SUMIFS(SCORES!$D$2:$D$2000,SCORES!$D$2:$D$2000,">=0")/(5*COUNTIFS(SCORES!$D$2:$D$2000,">=0")))*100) | N30: =IF(B30="","",IFERROR(INDEX(UNITS!$E$2:$E$2000,MATCH(B30,UNITS!$A$2:$A$2000,0)),"")) | O30: =IF(A30="","",IFERROR(COUNTIFS(SCORES!$C$2:$C$2000,A30,SCORES!$B$2:$B$2000,"C",SCORES!$D$2:$D$2000,">=4")/COUNTIFS(SCORES!$C$2:$C$2000,A30,SCORES!$B$2:$B$2000,"C",SCORES!$D$2:$D$2000,">=0"),"")) | P30: =IF(A30="","",IFERROR(COUNTIFS(SCORES!$C$2:$C$2000,A30,SCORES!$B$2:$B$2000,"J",SCORES!$D$2:$D$2000,">=4")/COUNTIFS(SCORES!$C$2:$C$2000,A30,SCORES!$B$2:$B$2000,"J",SCORES!$D$2:$D$2000,">=0"),"")) | Q30: =IF(OR(O30="",P30=""),"",(O30-P30)*100)
A31: {=IFERROR(INDEX(CHECKS!$A$2:$A$2000,SMALL(IF(CHECKS!$E$2:$E$2000="y",ROW(CHECKS!$E$2:$E$2000)-1),27)),"")} | B31: =IF(A31="","",INDEX(CHECKS!$C$2:$C$2000,MATCH(A31,CHECKS!$A$2:$A$2000,0))) | C31: =IF(A31="","",SUMIFS(RECHECKS!$G$2:$G$2000,RECHECKS!$C$2:$C$2000,A31)) | D31: =IF(OR(A31="",C31=0),"",SUMIFS(RECHECKS!$F$2:$F$2000,RECHECKS!$C$2:$C$2000,A31,RECHECKS!$G$2:$G$2000,1)/(5*C31)) | E31: =IF(OR(A31="",C31=0),"",SUMIFS(RECHECKS!$D$2:$D$2000,RECHECKS!$C$2:$C$2000,A31,RECHECKS!$G$2:$G$2000,1)/(3*C31)) | F31: =IF(D31="","",(E31-D31)*100) | G31: =IF(A31="","",INDEX(CHECKS!$F$2:$F$2000,MATCH(A31,CHECKS!$A$2:$A$2000,0))&"") | H31: =IF(OR(A31="",G31=""),"",SUMIFS(RECHECKS!$J$2:$J$2000,RECHECKS!$C$2:$C$2000,A31)) | I31: =IF(OR(H31="",H31=0),"",SUMIFS(RECHECKS!$I$2:$I$2000,RECHECKS!$C$2:$C$2000,A31,RECHECKS!$J$2:$J$2000,1)/(5*H31)) | J31: =IF(OR(H31="",H31=0),"",SUMIFS(RECHECKS!$E$2:$E$2000,RECHECKS!$C$2:$C$2000,A31,RECHECKS!$J$2:$J$2000,1)/(2*H31)) | K31: =IF(I31="","",(J31-I31)*100) | L31: =IF(F31="","",IF(K31="",F31,F31-K31)) | M31: =IF(A31="","",(SUMIFS(SCORES!$D$2:$D$2000,SCORES!$C$2:$C$2000,A31)/(5*COUNTIFS(SCORES!$C$2:$C$2000,A31,SCORES!$D$2:$D$2000,">=0"))-SUMIFS(SCORES!$D$2:$D$2000,SCORES!$D$2:$D$2000,">=0")/(5*COUNTIFS(SCORES!$D$2:$D$2000,">=0")))*100) | N31: =IF(B31="","",IFERROR(INDEX(UNITS!$E$2:$E$2000,MATCH(B31,UNITS!$A$2:$A$2000,0)),"")) | O31: =IF(A31="","",IFERROR(COUNTIFS(SCORES!$C$2:$C$2000,A31,SCORES!$B$2:$B$2000,"C",SCORES!$D$2:$D$2000,">=4")/COUNTIFS(SCORES!$C$2:$C$2000,A31,SCORES!$B$2:$B$2000,"C",SCORES!$D$2:$D$2000,">=0"),"")) | P31: =IF(A31="","",IFERROR(COUNTIFS(SCORES!$C$2:$C$2000,A31,SCORES!$B$2:$B$2000,"J",SCORES!$D$2:$D$2000,">=4")/COUNTIFS(SCORES!$C$2:$C$2000,A31,SCORES!$B$2:$B$2000,"J",SCORES!$D$2:$D$2000,">=0"),"")) | Q31: =IF(OR(O31="",P31=""),"",(O31-P31)*100)
A32: {=IFERROR(INDEX(CHECKS!$A$2:$A$2000,SMALL(IF(CHECKS!$E$2:$E$2000="y",ROW(CHECKS!$E$2:$E$2000)-1),28)),"")} | B32: =IF(A32="","",INDEX(CHECKS!$C$2:$C$2000,MATCH(A32,CHECKS!$A$2:$A$2000,0))) | C32: =IF(A32="","",SUMIFS(RECHECKS!$G$2:$G$2000,RECHECKS!$C$2:$C$2000,A32)) | D32: =IF(OR(A32="",C32=0),"",SUMIFS(RECHECKS!$F$2:$F$2000,RECHECKS!$C$2:$C$2000,A32,RECHECKS!$G$2:$G$2000,1)/(5*C32)) | E32: =IF(OR(A32="",C32=0),"",SUMIFS(RECHECKS!$D$2:$D$2000,RECHECKS!$C$2:$C$2000,A32,RECHECKS!$G$2:$G$2000,1)/(3*C32)) | F32: =IF(D32="","",(E32-D32)*100) | G32: =IF(A32="","",INDEX(CHECKS!$F$2:$F$2000,MATCH(A32,CHECKS!$A$2:$A$2000,0))&"") | H32: =IF(OR(A32="",G32=""),"",SUMIFS(RECHECKS!$J$2:$J$2000,RECHECKS!$C$2:$C$2000,A32)) | I32: =IF(OR(H32="",H32=0),"",SUMIFS(RECHECKS!$I$2:$I$2000,RECHECKS!$C$2:$C$2000,A32,RECHECKS!$J$2:$J$2000,1)/(5*H32)) | J32: =IF(OR(H32="",H32=0),"",SUMIFS(RECHECKS!$E$2:$E$2000,RECHECKS!$C$2:$C$2000,A32,RECHECKS!$J$2:$J$2000,1)/(2*H32)) | K32: =IF(I32="","",(J32-I32)*100) | L32: =IF(F32="","",IF(K32="",F32,F32-K32)) | M32: =IF(A32="","",(SUMIFS(SCORES!$D$2:$D$2000,SCORES!$C$2:$C$2000,A32)/(5*COUNTIFS(SCORES!$C$2:$C$2000,A32,SCORES!$D$2:$D$2000,">=0"))-SUMIFS(SCORES!$D$2:$D$2000,SCORES!$D$2:$D$2000,">=0")/(5*COUNTIFS(SCORES!$D$2:$D$2000,">=0")))*100) | N32: =IF(B32="","",IFERROR(INDEX(UNITS!$E$2:$E$2000,MATCH(B32,UNITS!$A$2:$A$2000,0)),"")) | O32: =IF(A32="","",IFERROR(COUNTIFS(SCORES!$C$2:$C$2000,A32,SCORES!$B$2:$B$2000,"C",SCORES!$D$2:$D$2000,">=4")/COUNTIFS(SCORES!$C$2:$C$2000,A32,SCORES!$B$2:$B$2000,"C",SCORES!$D$2:$D$2000,">=0"),"")) | P32: =IF(A32="","",IFERROR(COUNTIFS(SCORES!$C$2:$C$2000,A32,SCORES!$B$2:$B$2000,"J",SCORES!$D$2:$D$2000,">=4")/COUNTIFS(SCORES!$C$2:$C$2000,A32,SCORES!$B$2:$B$2000,"J",SCORES!$D$2:$D$2000,">=0"),"")) | Q32: =IF(OR(O32="",P32=""),"",(O32-P32)*100)
A33: {=IFERROR(INDEX(CHECKS!$A$2:$A$2000,SMALL(IF(CHECKS!$E$2:$E$2000="y",ROW(CHECKS!$E$2:$E$2000)-1),29)),"")} | B33: =IF(A33="","",INDEX(CHECKS!$C$2:$C$2000,MATCH(A33,CHECKS!$A$2:$A$2000,0))) | C33: =IF(A33="","",SUMIFS(RECHECKS!$G$2:$G$2000,RECHECKS!$C$2:$C$2000,A33)) | D33: =IF(OR(A33="",C33=0),"",SUMIFS(RECHECKS!$F$2:$F$2000,RECHECKS!$C$2:$C$2000,A33,RECHECKS!$G$2:$G$2000,1)/(5*C33)) | E33: =IF(OR(A33="",C33=0),"",SUMIFS(RECHECKS!$D$2:$D$2000,RECHECKS!$C$2:$C$2000,A33,RECHECKS!$G$2:$G$2000,1)/(3*C33)) | F33: =IF(D33="","",(E33-D33)*100) | G33: =IF(A33="","",INDEX(CHECKS!$F$2:$F$2000,MATCH(A33,CHECKS!$A$2:$A$2000,0))&"") | H33: =IF(OR(A33="",G33=""),"",SUMIFS(RECHECKS!$J$2:$J$2000,RECHECKS!$C$2:$C$2000,A33)) | I33: =IF(OR(H33="",H33=0),"",SUMIFS(RECHECKS!$I$2:$I$2000,RECHECKS!$C$2:$C$2000,A33,RECHECKS!$J$2:$J$2000,1)/(5*H33)) | J33: =IF(OR(H33="",H33=0),"",SUMIFS(RECHECKS!$E$2:$E$2000,RECHECKS!$C$2:$C$2000,A33,RECHECKS!$J$2:$J$2000,1)/(2*H33)) | K33: =IF(I33="","",(J33-I33)*100) | L33: =IF(F33="","",IF(K33="",F33,F33-K33)) | M33: =IF(A33="","",(SUMIFS(SCORES!$D$2:$D$2000,SCORES!$C$2:$C$2000,A33)/(5*COUNTIFS(SCORES!$C$2:$C$2000,A33,SCORES!$D$2:$D$2000,">=0"))-SUMIFS(SCORES!$D$2:$D$2000,SCORES!$D$2:$D$2000,">=0")/(5*COUNTIFS(SCORES!$D$2:$D$2000,">=0")))*100) | N33: =IF(B33="","",IFERROR(INDEX(UNITS!$E$2:$E$2000,MATCH(B33,UNITS!$A$2:$A$2000,0)),"")) | O33: =IF(A33="","",IFERROR(COUNTIFS(SCORES!$C$2:$C$2000,A33,SCORES!$B$2:$B$2000,"C",SCORES!$D$2:$D$2000,">=4")/COUNTIFS(SCORES!$C$2:$C$2000,A33,SCORES!$B$2:$B$2000,"C",SCORES!$D$2:$D$2000,">=0"),"")) | P33: =IF(A33="","",IFERROR(COUNTIFS(SCORES!$C$2:$C$2000,A33,SCORES!$B$2:$B$2000,"J",SCORES!$D$2:$D$2000,">=4")/COUNTIFS(SCORES!$C$2:$C$2000,A33,SCORES!$B$2:$B$2000,"J",SCORES!$D$2:$D$2000,">=0"),"")) | Q33: =IF(OR(O33="",P33=""),"",(O33-P33)*100)
A34: {=IFERROR(INDEX(CHECKS!$A$2:$A$2000,SMALL(IF(CHECKS!$E$2:$E$2000="y",ROW(CHECKS!$E$2:$E$2000)-1),30)),"")} | B34: =IF(A34="","",INDEX(CHECKS!$C$2:$C$2000,MATCH(A34,CHECKS!$A$2:$A$2000,0))) | C34: =IF(A34="","",SUMIFS(RECHECKS!$G$2:$G$2000,RECHECKS!$C$2:$C$2000,A34)) | D34: =IF(OR(A34="",C34=0),"",SUMIFS(RECHECKS!$F$2:$F$2000,RECHECKS!$C$2:$C$2000,A34,RECHECKS!$G$2:$G$2000,1)/(5*C34)) | E34: =IF(OR(A34="",C34=0),"",SUMIFS(RECHECKS!$D$2:$D$2000,RECHECKS!$C$2:$C$2000,A34,RECHECKS!$G$2:$G$2000,1)/(3*C34)) | F34: =IF(D34="","",(E34-D34)*100) | G34: =IF(A34="","",INDEX(CHECKS!$F$2:$F$2000,MATCH(A34,CHECKS!$A$2:$A$2000,0))&"") | H34: =IF(OR(A34="",G34=""),"",SUMIFS(RECHECKS!$J$2:$J$2000,RECHECKS!$C$2:$C$2000,A34)) | I34: =IF(OR(H34="",H34=0),"",SUMIFS(RECHECKS!$I$2:$I$2000,RECHECKS!$C$2:$C$2000,A34,RECHECKS!$J$2:$J$2000,1)/(5*H34)) | J34: =IF(OR(H34="",H34=0),"",SUMIFS(RECHECKS!$E$2:$E$2000,RECHECKS!$C$2:$C$2000,A34,RECHECKS!$J$2:$J$2000,1)/(2*H34)) | K34: =IF(I34="","",(J34-I34)*100) | L34: =IF(F34="","",IF(K34="",F34,F34-K34)) | M34: =IF(A34="","",(SUMIFS(SCORES!$D$2:$D$2000,SCORES!$C$2:$C$2000,A34)/(5*COUNTIFS(SCORES!$C$2:$C$2000,A34,SCORES!$D$2:$D$2000,">=0"))-SUMIFS(SCORES!$D$2:$D$2000,SCORES!$D$2:$D$2000,">=0")/(5*COUNTIFS(SCORES!$D$2:$D$2000,">=0")))*100) | N34: =IF(B34="","",IFERROR(INDEX(UNITS!$E$2:$E$2000,MATCH(B34,UNITS!$A$2:$A$2000,0)),"")) | O34: =IF(A34="","",IFERROR(COUNTIFS(SCORES!$C$2:$C$2000,A34,SCORES!$B$2:$B$2000,"C",SCORES!$D$2:$D$2000,">=4")/COUNTIFS(SCORES!$C$2:$C$2000,A34,SCORES!$B$2:$B$2000,"C",SCORES!$D$2:$D$2000,">=0"),"")) | P34: =IF(A34="","",IFERROR(COUNTIFS(SCORES!$C$2:$C$2000,A34,SCORES!$B$2:$B$2000,"J",SCORES!$D$2:$D$2000,">=4")/COUNTIFS(SCORES!$C$2:$C$2000,A34,SCORES!$B$2:$B$2000,"J",SCORES!$D$2:$D$2000,">=0"),"")) | Q34: =IF(OR(O34="",P34=""),"",(O34-P34)*100)
A35: {=IFERROR(INDEX(CHECKS!$A$2:$A$2000,SMALL(IF(CHECKS!$E$2:$E$2000="y",ROW(CHECKS!$E$2:$E$2000)-1),31)),"")} | B35: =IF(A35="","",INDEX(CHECKS!$C$2:$C$2000,MATCH(A35,CHECKS!$A$2:$A$2000,0))) | C35: =IF(A35="","",SUMIFS(RECHECKS!$G$2:$G$2000,RECHECKS!$C$2:$C$2000,A35)) | D35: =IF(OR(A35="",C35=0),"",SUMIFS(RECHECKS!$F$2:$F$2000,RECHECKS!$C$2:$C$2000,A35,RECHECKS!$G$2:$G$2000,1)/(5*C35)) | E35: =IF(OR(A35="",C35=0),"",SUMIFS(RECHECKS!$D$2:$D$2000,RECHECKS!$C$2:$C$2000,A35,RECHECKS!$G$2:$G$2000,1)/(3*C35)) | F35: =IF(D35="","",(E35-D35)*100) | G35: =IF(A35="","",INDEX(CHECKS!$F$2:$F$2000,MATCH(A35,CHECKS!$A$2:$A$2000,0))&"") | H35: =IF(OR(A35="",G35=""),"",SUMIFS(RECHECKS!$J$2:$J$2000,RECHECKS!$C$2:$C$2000,A35)) | I35: =IF(OR(H35="",H35=0),"",SUMIFS(RECHECKS!$I$2:$I$2000,RECHECKS!$C$2:$C$2000,A35,RECHECKS!$J$2:$J$2000,1)/(5*H35)) | J35: =IF(OR(H35="",H35=0),"",SUMIFS(RECHECKS!$E$2:$E$2000,RECHECKS!$C$2:$C$2000,A35,RECHECKS!$J$2:$J$2000,1)/(2*H35)) | K35: =IF(I35="","",(J35-I35)*100) | L35: =IF(F35="","",IF(K35="",F35,F35-K35)) | M35: =IF(A35="","",(SUMIFS(SCORES!$D$2:$D$2000,SCORES!$C$2:$C$2000,A35)/(5*COUNTIFS(SCORES!$C$2:$C$2000,A35,SCORES!$D$2:$D$2000,">=0"))-SUMIFS(SCORES!$D$2:$D$2000,SCORES!$D$2:$D$2000,">=0")/(5*COUNTIFS(SCORES!$D$2:$D$2000,">=0")))*100) | N35: =IF(B35="","",IFERROR(INDEX(UNITS!$E$2:$E$2000,MATCH(B35,UNITS!$A$2:$A$2000,0)),"")) | O35: =IF(A35="","",IFERROR(COUNTIFS(SCORES!$C$2:$C$2000,A35,SCORES!$B$2:$B$2000,"C",SCORES!$D$2:$D$2000,">=4")/COUNTIFS(SCORES!$C$2:$C$2000,A35,SCORES!$B$2:$B$2000,"C",SCORES!$D$2:$D$2000,">=0"),"")) | P35: =IF(A35="","",IFERROR(COUNTIFS(SCORES!$C$2:$C$2000,A35,SCORES!$B$2:$B$2000,"J",SCORES!$D$2:$D$2000,">=4")/COUNTIFS(SCORES!$C$2:$C$2000,A35,SCORES!$B$2:$B$2000,"J",SCORES!$D$2:$D$2000,">=0"),"")) | Q35: =IF(OR(O35="",P35=""),"",(O35-P35)*100)
